Workbook

Sheet INPUT-Y
B1: BALANCE SHEET | C1: 2013 | D1: 2014 | E1: 2015 | F1: 2016 | G1: 2017 | H1: 2018 | I1: 2019 | J1: 2020
B2: A. CURRENT ASSETS | C2: 405.1 | D2: 435.1 | E2: 484.5 | F2: 341.9 | G2: 485.8 | H2: 1229.9 | I2: 1190.4 | J2: 1779.3
B3: I. Cash and Cash Equivalents | C3: 30.1 | D3: 97.8 | E3: 88.7 | F3: 68 | G3: 223 | H3: 609.4 | I3: 105.4 | J3: 135.4
B4: 1. Cash | C4: 26.4 | D4: 80.6 | E4: 17.2 | F4: 15.1 | G4: 79.5 | H4: 48.7 | I4: 41.4 | J4: 69.7
B5: 2. Cash equivalents | C5: 3.7 | D5: 17.2 | E5: 71.5 | F5: 52.9 | G5: 143.5 | H5: 560.7 | I5: 64 | J5: 65.7
B6: II. Short-term Financial Investment | C6: 255.4 | D6: 219 | E6: 0 | F6: 0 | G6: 8.2 | H6: 252 | I6: 12 | J6: 0
B7: 1. Securities available for sale | C7: 0 | D7: 0 | E7: 0 | F7: 0 | G7: 0 | H7: 0 | I7: 0 | J7: 0
B8: 2. Provision for decline in value of investments in securities | C8: -21.9 | D8: -0.3 | E8: 0 | F8: 0 | G8: 0 | H8: 0 | I8: 0 | J8: 0
B9: 3. Securities hold to maturity | C9: 277.3 | D9: 219.3 | E9: 0 | F9: 0 | G9: 8.2 | H9: 252 | I9: 12 | J9: 0
B10: III. Short-term Receivables | C10: 93.3 | D10: 94.5 | E10: 381 | F10: 257 | G10: 227.4 | H10: 245.5 | I10: 688.2 | J10: 1434.3
B11: 1. Short-term receivables from customers | C11: 46.3 | D11: 38.1 | E11: 107.6 | F11: 121.4 | G11: 74.7 | H11: 109.6 | I11: 213.5 | J11: 321.1
B12: 2. Prepaid for suppliers | C12: 42.1 | D12: 52.4 | E12: 96 | F12: 3.2 | G12: 50.1 | H12: 103.3 | I12: 74.3 | J12: 466.2
... B41: 2. Fixed assets of finance leasing | C41: 0 | D41: 0 | E41: 0 | F41: 0 | G41: 0 | H41: 0 | I41: 0 | J41: 27.8
B42: - Cost | C42: 0 | D42: 0 | E42: 0 | F42: 0 | G42: 0 | H42: 0 | I42: 0 | J42: 28.1 | L42: =L390 -> 0
B43: - Accumulated depreciation | C43: 0 | D43: 0 | E43: 0 | F43: 0 | G43: 0 | H43: 0 | I43: 0 | J43: -0.3
B44: 3. Intangible fixed assets | C44: 1.7 | D44: 1.7 | E44: 5.7 | F44: 5.6 | G44: 6.6 | H44: 6.4 | I44: 19.2 | J44: 16.7
B45: - Cost | C45: 2 | D45: 2 | E45: 6.2 | F45: 6.4 | G45: 7.5 | H45: 7.4 | I45: 21.1 | J45: 21.3
B46: - Accumulated depreciation | C46: -0.3 | D46: -0.3 | E46: -0.5 | F46: -0.7 | G46: -0.9 | H46: -1 | I46: -1.9 | J46: -4.6
B47: III. Investment properties | C47: 0 | D47: 0 | E47: 0 | F47: 0 | G47: 0 | H47: 0 | I47: 0 | J47: 0
B48: 1. Cost | C48: 0 | D48: 0 | E48: 0 | F48: 0 | G48: 0 | H48: 0 | I48: 0 | J48: 0
B49: 2. Accumulated depreciation | C49: 0 | D49: 0 | E49: 0 | F49: 0 | G49: 0 | H49: 0 | I49: 0 | J49: 0
B50: IV. Long term assets in progress | C50: 136.9 | D50: 119.6 | E50: 135.2 | F50: 5.6 | G50: 18 | H50: 215.8 | I50: 262.8 | J50: 541.4
B51: 1. Long term work in progress | C51: 0 | D51: 0 | E51: 0 | F51: 0 | G51: 0 | H51: 0 | I51: 0 | J51: 0
B52: 2. Long term construction in progress | C52: 136.9 | D52: 119.6 | E52: 135.2 | F52: 5.6 | G52: 18 | H52: 215.8 | I52: 262.8 | J52: 541.4
B53: V. Long-term investments | C53: 72.5 | D53: 0.7 | E53: 0.9 | F53: 0.2 | G53: 0 | H53: 0 | I53: 2.6 | J53: 0
B54: 1. Investments in subsidiary | C54: 0 | D54: 0 | E54: 0 | F54: 0 | G54: 0 | H54: 0 | I54: 0 | J54: 0
... B118: TOTAL EQUITY | C118: 1725.2 | D118: 1710.3 | E118: 1885.2 | F118: 1551.7 | G118: 1658.6 | H118: 4360.6 | I118: 6763.2 | J118: 7773.1
B120: INCOME STATEMENT
B121: 1. Revenue from sale of goods and services | C121: 307.9 | D121: 338.8 | E121: 354.4 | F121: 431.4 | G121: 539.1 | H121: 559.5 | I121: 1159.4 | J121: 1494.5
B122: 2. Deduction | C122: 0 | D122: 0 | E122: 0 | F122: 0 | G122: 0 | H122: 0 | I122: 0 | J122: 1.2
B123: 3. Net revenue from sale of goods and services | C123: 307.9 | D123: 338.8 | E123: 354.4 | F123: 431.4 | G123: 539.1 | H123: 559.5 | I123: 1159.4 | J123: 1493.3
B124: 4. Costs of goods sold | C124: 118.2 | D124: 134.5 | E124: 157.3 | F124: 212.5 | G124: 227.3 | H124: 253.5 | I124: 509.7 | J124: 732.7
B125: 5. Gross profit | C125: 189.7 | D125: 204.3 | E125: 197 | F125: 218.9 | G125: 311.8 | H125: 306 | I125: 649.7 | J125: 760.7
B126: 6. Income from financial activities | C126: 33.8 | D126: 44.6 | E126: 34.4 | F126: 26.8 | G126: 18 | H126: 19.5 | I126: 24.2 | J126: 30.5
B127: 7. Expenses from financial activities | C127: 97.9 | D127: 76.3 | E127: 41.4 | F127: 45.8 | G127: 24.6 | H127: 41.1 | I127: 257.8 | J127: 371.2
B128: - In which: Interest expenses | C128: 78.3 | D128: 59.5 | E128: 41.1 | F128: 39.1 | G128: 24.4 | H128: 40.2 | I128: 244.9 | J128: 354.4
B129: 8. Share in profits of associates | C129: 6.5 | D129: 0 | E129: 0 | F129: 0 | G129: 0 | H129: 0 | I129: 0 | J129: 0
B130: 9. Selling expenses | C130: 0 | D130: 0.2 | E130: 0 | F130: 0.1 | G130: 1 | H130: 0.6 | I130: 0.6 | J130: 1.7
B131: 10. General and administrative expenses | C131: 30.3 | D131: 40.4 | E131: 42.1 | F131: 51.3 | G131: 65.1 | H131: 76.6 | I131: 111.2 | J131: 114.3
B132: 11. Operating profit | C132: 101.8 | D132: 132.1 | E132: 147.8 | F132: 148.5 | G132: 239.2 | H132: 207.1 | I132: 304.3 | J132: 303.9
...

Sheet IS
B1: 2016 | C1: 2017 | D1: 2018 | E1: 2019 | F1: 2020 | G1: 2021F | H1: 2022F | I1: 2023F | J1: 2024F | K1: 2025F
A2: INCOME STATEMENT | B2: HISTORICAL | G2: FORECAST
A4: Net Sales | B4: 431.4 | C4: 539.1 | D4: 559.5 | E4: 1159.4 | F4: 1494.5 | G4: =Forecast!T18 -> 1450 | H4: =Forecast!U18 -> 3182 | I4: =Forecast!V18 -> 3284 | J4: =Forecast!W18 -> 3289 | K4: =Forecast!X18 -> 3299
A5: Cost of goods sold | B5: =-'INPUT-Y'!F124 -> -212.5 | C5: =-'INPUT-Y'!G124 -> -227.3 | D5: =-'INPUT-Y'!H124 -> -253.5 | E5: =-'INPUT-Y'!I124 -> -509.7 | F5: =-'INPUT-Y'!J124 -> -732.7 | G5: =-SUM(Forecast!G118:G122) -> -628.86298 | H5: =-SUM(Forecast!H118:H122) -> -1676.9805 | I5: =-SUM(Forecast!I118:I122) -> -1700.3699 | J5: =-SUM(Forecast!J118:J122) -> -1722.618 | K5: =-SUM(Forecast!K118:K122) -> -1745.9574
A6: Gross profit | B6: =B4+B5 -> 218.9 | C6: =C4+C5 -> 311.8 | D6: =D4+D5 -> 306 | E6: =E4+E5 -> 649.7 | F6: =F4+F5 -> 761.8 | G6: =G4+G5 -> 821.13702 | H6: =H4+H5 -> 1505.0195 | I6: =I4+I5 -> 1583.6301 | ... K6: =K4+K5 -> 1553.0426
A7: Financial income | B7: ='INPUT-Y'!F126 -> 26.8 | C7: ='INPUT-Y'!G126 -> 18 | D7: ='INPUT-Y'!H126 -> 19.5 | E7: ='INPUT-Y'!I126 -> 24.2 | F7: ='INPUT-Y'!J126 -> 30.5 | G7: =G36 -> 36.797895 | H7: =H36 -> 70.70286 | I7: =I36 -> 74.443519 | J7: =J36 -> 77.034999 | K7: =K36 -> 75.118441
A8: Financial Expenses | B8: =-'INPUT-Y'!F127 -> -45.8 | C8: =-'INPUT-Y'!G127 -> -24.6 | D8: =-'INPUT-Y'!H127 -> -41.1 | E8: =-'INPUT-Y'!I127 -> -257.8 | F8: =-'INPUT-Y'!J127 -> -371.2 | G8: =G39 -> -343.64435 | H8: =H39 -> -834.6402 | I8: =I39 -> -805.55427 | J8: =J39 -> -775.37795 | K8: =K39 -> -745.25784
A9: Of which: Interest Expenses | B9: =-'INPUT-Y'!F128 -> -39.1 | C9: =-'INPUT-Y'!G128 -> -24.4 | D9: =-'INPUT-Y'!H128 -> -40.2 | E9: =-'INPUT-Y'!I128 -> -244.9 | F9: =-'INPUT-Y'!J128 -> -354.4 | G9: =G40 -> -327.34458 | H9: =H40 -> -798.87064 | I9: =I40 -> -768.63812 | J9: =J40 -> -738.40559 | K9: =K40 -> -708.17306
A10: Selling Expenses | B10: =-'INPUT-Y'!F130 -> -0.1 | C10: =-'INPUT-Y'!G130 -> -1 | D10: =-'INPUT-Y'!H130 -> -0.6 | E10: =-'INPUT-Y'!I130 -> -0.6 | F10: =-'INPUT-Y'!J130 -> -1.7 | G10: =G29*G4 -> -1.318243 | H10: =H29*H4 -> -2.7197045 | I10: =I29*I4 -> -3.1760141 | J10: =J29*J4 -> -2.9940492 | K10: =K29*K4 -> -3.0044598
A11: General and admin expenses | B11: =-'INPUT-Y'!F131 -> -51.3 | C11: =-'INPUT-Y'!G131 -> -65.1 | D11: =-'INPUT-Y'!H131 -> -76.6 | E11: =-'INPUT-Y'!I131 -> -111.2 | F11: =-'INPUT-Y'!J131 -> -114.3 | G11: =G33*G4 -> -149.49503 | H11: =H33*H4 -> -292.20532 | I11: =I33*I4 -> -297.10475 | J11: =J33*J4 -> -312.89476 | K11: =K33*K4 -> -305.0858
A12: Net Profit/Loss from Operating activities | B12: ='INPUT-Y'!F132 -> 148.5 | C12: ='INPUT-Y'!G132 -> 239.2 | D12: ='INPUT-Y'!H132 -> 207.1 | E12: ='INPUT-Y'!I132 -> 304.3 | F12: ='INPUT-Y'!J132 -> 303.9 | G12: =G6+G7+SUM(G8,G10,G11) -> 363.4773 | H12: =H6+H7+SUM(H8,H10,H11) -> 446.15716 | I12: =I6+I7+SUM(I8,I10,I11) -> 552.23861 | J12: =J6+J7+SUM(J8,J10,J11) -> 552.15026 | K12: =K6+K7+SUM(K8,K10,K11) -> 574.81292
A13: Other profits/(loss) | B13: ='INPUT-Y'!F135 -> 0.7 | C13: ='INPUT-Y'!G135 -> -8.7 | D13: ='INPUT-Y'!H135 -> -0.2 | E13: ='INPUT-Y'!I135 -> -0.3 | F13: ='INPUT-Y'!J135 -> 4.7 | G13: =F13 -> 4.7 | H13: =G13 -> 4.7 | I13: =H13 -> 4.7 | J13: =I13 -> 4.7 | K13: =J13 -> 4.7
A14: Profit or lost from join venture companies | B14: ='INPUT-Y'!F129 -> 0 | C14: ='INPUT-Y'!G129 -> 0 | D14: ='INPUT-Y'!H129 -> 0 | E14: ='INPUT-Y'!I129 -> 0 | F14: ='INPUT-Y'!J129 -> 0 | G14: 0 | H14: 0 | I14: 0 | J14: 0 | K14: 0
A15: Total profit before tax | B15: ='INPUT-Y'!F136 -> 149.2 | C15: ='INPUT-Y'!G136 -> 230.4 | D15: ='INPUT-Y'!H136 -> 206.9 | E15: ='INPUT-Y'!I136 -> 303.9 | F15: ='INPUT-Y'!J136 -> 308.6 | G15: =SUM(G12:G14) -> 368.1773 | H15: =SUM(H12:H14) -> 450.85716 | I15: =SUM(I12:I14) -> 556.93861 | J15: =SUM(J12:J14) -> 556.85026 | K15: =SUM(K12:K14) -> 579.51292
A16: Current Corporate Income Tax Expenses | B16: =-'INPUT-Y'!F137 -> -13.1 | C16: =-'INPUT-Y'!G137 -> -21.4 | D16: =-'INPUT-Y'!H137 -> -20.6 | E16: =-'INPUT-Y'!I137 -> -13.7 | F16: =-'INPUT-Y'!J137 -> -14.1 | G16: =-7.5%*G15 -> -27.613297 | H16: =-7%*H15 -> -31.560001 | I16: =-7%*I15 -> -38.985702 | J16: =-4.5%*J15 -> -25.058262 | K16: =-5%*K15 -> -28.975646
A17: Deferred Income Taxes Expenses | B17: ='INPUT-Y'!F138 -> 1.8 | C17: ='INPUT-Y'!G138 -> -0.3 | D17: ='INPUT-Y'!H138 -> -1 | E17: ='INPUT-Y'!I138 -> -0.3 | F17: ='INPUT-Y'!J138 -> -0.5 | G17: =AVERAGE(D17:F17) -> -0.6 | H17: =AVERAGE(F17:G17) -> -0.55 | I17: =AVERAGE(G17:H17) -> -0.575 | J17: =AVERAGE(H17:I17) -> -0.5625 | K17: =AVERAGE(I17:J17) -> -0.56875
A18: Net profit after tax | B18: ='INPUT-Y'!F139 -> 134.4 | C18: ='INPUT-Y'!G139 -> 209.3 | D18: ='INPUT-Y'!H139 -> 187.3 | E18: ='INPUT-Y'!I139 -> 290.5 | F18: ='INPUT-Y'!J139 -> 295 | G18: =SUM(G15:G17) -> 339.964 | H18: =SUM(H15:H17) -> 418.74716 | I18: =SUM(I15:I17) -> 517.3779 | J18: =SUM(J15:J17) -> 531.2295 | K18: =SUM(K15:K17) -> 549.96853
A19: Benefits of Minitory shareholders | B19: =-'INPUT-Y'!F140 -> -39.3 | C19: =-'INPUT-Y'!G140 -> -55.5 | D19: =-'INPUT-Y'!H140 -> -42.6 | E19: =-'INPUT-Y'!I140 -> -39.5 | F19: =-'INPUT-Y'!J140 -> -37.6 | G19: =AVERAGE(D19:F19) -> -39.9 | H19: =AVERAGE(E19:G19) -> -39 | I19: =AVERAGE(F19:H19) -> -38.833333 | J19: =AVERAGE(G19:I19) -> -39.244444 | K19: =AVERAGE(H19:J19) -> -39.025926
A20: Net profit after tax attributable to parent company shareholders | B20: ='INPUT-Y'!F141 -> 95.1 | C20: ='INPUT-Y'!G141 -> 153.8 | D20: ='INPUT-Y'!H141 -> 144.7 | E20: ='INPUT-Y'!I141 -> 251 | F20: ='INPUT-Y'!J141 -> 257.4 | G20: =SUM(G18:G19) -> 300.064 | H20: =SUM(H18:H19) -> 379.74716 | I20: =SUM(I18:I19) -> 478.54457 | J20: =SUM(J18:J19) -> 491.98506 | K20: =SUM(K18:K19) -> 510.9426
A21: Basic EPS | B21: 1.276 | C21: 1.798 | D21: 1.254 | E21: 1.06 | F21: =1029/1000 -> 1.029 | G21: =G20/Valuation!$F$56 -> 0.98796259 | H21: =H20/Valuation!$F$56 -> 1.2503199 | I21: =I20/Valuation!$F$56 -> 1.575611 | J21: =J20/Valuation!$F$56 -> 1.6198639 | K21: =K20/Valuation!$F$56 -> 1.6822817
A22: Diluted EPS | E22: 1.06 | F22: =1029/1000 -> 1.029
A23: OPERATING ASSUMPTIONS
A24: Revenue growth | B24: 0 | C24: =Forecast!P18/Forecast!O18 -1 -> 0.24965229 | D24: =Forecast!Q18/Forecast!P18 -1 -> 0.037840846 | E24: =Forecast!R18/Forecast!Q18 -1 -> 1.0722073 | F24: =Forecast!S18/Forecast!R18 -1 -> 0.28799379 | G24: =Forecast!T18/Forecast!S18 -1 -> -0.028996183 | H24: =Forecast!U18/Forecast!T18 -1 -> 1.1944828 | I24: =Forecast!V18/Forecast!U18 -1 -> 0.032055311 | J24: =Forecast!W18/Forecast!V18 -1 -> 0.0015225335 | K24: =Forecast!X18/Forecast!W18 -1 -> 0.0030404378
A25: COGS growth | B25: 0 | C25: =Forecast!C117/Forecast!B117 -1 -> 0.11140584 | D25: =Forecast!D117/Forecast!C117 -1 -> 0.063075349 | E25: =Forecast!E117/Forecast!D117 -1 -> 0.63470173 | F25: =Forecast!F117/Forecast!E117 -1 -> 0.43751226 | G25: =Forecast!G117/Forecast!F117 -1 -> -0.14171833 | H25: =Forecast!H117/Forecast!G117 -1 -> 1.6666866 | I25: =Forecast!I117/Forecast!H117 -1 -> 0.013947328 | J25: =Forecast!J117/Forecast!I117 -1 -> 0.013084271 | K25: =Forecast!K117/Forecast!J117 -1 -> 0.013548821
A26: Gross profit margin | B26: 0 | C26: =C6/B6 -1 -> 0.4243947 | D26: =D6/C6 -1 -> -0.018601668 | E26: =E6/D6 -1 -> 1.1232026 | F26: =F6/E6 -1 -> 0.17254117 | G26: =G6/F6 -1 -> 0.077890552 | H26: =H6/G6 -1 -> 0.83284821 | I26: =I6/H6 -1 -> 0.052232282 | J26: =J6/I6 -1 -> -0.010891495 | K26: =K6/J6 -1 -> -0.0085160847
A28: Selling expense
A29: Selling expense/Net revenue | B29: =B10/B4 -> -0.00023180343 | C29: =C10/C4 -> -0.0018549434 | D29: =D10/D4 -> -0.0010723861 | E29: =E10/E4 -> -0.00051750906 | F29: =F10/F4 -> -0.0011375042 | G29: =AVERAGE(D29:F29) -> -0.0009091331 | H29: =AVERAGE(E29:G29) -> -0.00085471545 | I29: =AVERAGE(F29:H29) -> -0.00096711758 | J29: =AVERAGE(G29:I29) -> -0.00091032204 | K29: =AVERAGE(H29:J29) -> -0.00091071835
A30: Growth rate | C30: =C10/B10 -1 -> 9 | D30: =D10/C10 -1 -> -0.4 | E30: =E10/D10 -1 -> 0 | F30: =F10/E10 -1 -> 1.8333333 | G30: 0.235 | H30: 0.125 | I30: 0.112 | J30: 0.127 | K30: 0.116
A32: G&A expense
A33: G&A expense/Net revenue | B33: =B11/B4 -> -0.11891516 | C33: =C11/C4 -> -0.12075682 | D33: =D11/D4 -> -0.13690795 | E33: =E11/E4 -> -0.095911678 | F33: =F11/F4 -> -0.076480428 | G33: =AVERAGE(D33:F33) -> -0.10310002 | H33: =AVERAGE(E33:G33) -> -0.091830709 | I33: =AVERAGE(F33:H33) -> -0.090470386 | J33: =AVERAGE(G33:I33) -> -0.095133705 | K33: =AVERAGE(H33:J33) -> -0.092478267
A34: Growth rate | C34: =C11/B11 -1 -> 0.26900585 | D34: =D11/C11 -1 -> 0.17665131 | E34: =E11/D11 -1 -> 0.45169713 | F34: =F11/E11 -1 -> 0.027877698 | G34: =G11/F11 -1 -> 0.30791801 | H34: =H11/G11 -1 -> 0.9546156 | I34: =I11/H11 -1 -> 0.016767084 | J34: =J11/I11 -1 -> 0.053146269 | K34: =K11/J11 -1 -> -0.024957127
A36: Financial income | B36: =B7 -> 26.8 | C36: =C7 -> 18 | D36: =D7 -> 19.5 | E36: =E7 -> 24.2 | F36: =F7 -> 30.5 | G36: =G37*G4 -> 36.797895 | H36: =H37*H4 -> 70.70286 | I36: =I37*I4 -> 74.443519 | J36: =J37*J4 -> 77.034999 | K36: =K37*K4 -> 75.118441
A37: Financial income/Net revenue | B37: =B36/B4 -> 0.062123319 | C37: =C36/C4 -> 0.033388982 | D37: =D36/D4 -> 0.034852547 | E37: =E36/E4 -> 0.020872865 | F37: =F36/F4 -> 0.020408163 | G37: =AVERAGE(D37:F37) -> 0.025377858 | H37: =AVERAGE(E37:G37) -> 0.022219629 | I37: =AVERAGE(F37:H37) -> 0.02266855 | J37: =AVERAGE(G37:I37) -> 0.023422013 | K37: =AVERAGE(H37:J37) -> 0.022770064
A39: Financial expenses | B39: =B8 -> -45.8 | C39: =C8 -> -24.6 | D39: =D8 -> -41.1 | E39: =E8 -> -257.8 | F39: =F8 -> -371.2 | G39: =SUM(G40:G41) -> -343.64435 | H39: =SUM(H40:H41) -> -834.6402 | I39: =SUM(I40:I41) -> -805.55427 | J39: =SUM(J40:J41) -> -775.37795 | K39: =SUM(K40:K41) -> -745.25784
A40: Interest expense | B40: =B9 -> -39.1 | C40: =C9 -> -24.4 | D40: =D9 -> -40.2 | E40: =E9 -> -244.9 | F40: =F9 -> -354.4 | G40: =-Debt!J55/1000000 -> -327.34458 | H40: =-Debt!K55/1000000 -> -798.87064 | I40: =-Debt!L55/1000000 -> -768.63812 | J40: =-Debt!M55/1000000 -> -738.40559 | K40: =-Debt!N55/1000000 -> -708.17306
A41: Other financial expense | B41: =B39-B40 -> -6.7 | C41: =C39-C40 -> -0.2 | D41: =D39-D40 -> -0.9 | E41: =E39-E40 -> -12.9 | F41: =F39-F40 -> -16.8 | G41: =G42*G4 -> -16.299766 | H41: =H42*H4 -> -35.769555 | I41: =I42*I4 -> -36.916159 | J41: =J42*J4 -> -36.972365 | K41: =K42*K4 -> -37.084778
A42: Other financial expense/Net revenue | B42: =B41/B4 -> -0.01553083 | C42: =C41/C4 -> -0.00037098868 | D42: =D41/D4 -> -0.0016085791 | E42: =E41/E4 -> -0.011126445 | F42: =F41/F4 -> -0.011241218 | G42: =F42 -> -0.011241218 | H42: =G42 -> -0.011241218 | I42: =H42 -> -0.011241218 | J42: =I42 -> -0.011241218 | K42: =J42 -> -0.011241218

Sheet BS
B1: 2016A | C1: 2017A | D1: 2018A | E1: 2019A | F1: 2020A | G1: 2021F | H1: 2022F | I1: 2023F | J1: 2024F | K1: 2025F
A2: BALANCE SHEET (Billion VND) | B2: HISTORICAL | G2: FORECAST
A4: TOTAL ASSET | B4: ='INPUT-Y'!F65 -> 1551.7 | C4: ='INPUT-Y'!G65 -> 1658.6 | D4: ='INPUT-Y'!H65 -> 4360.6 | E4: ='INPUT-Y'!I65 -> 6763.2 | F4: ='INPUT-Y'!J65 -> 7773.1 | G4: =SUM(G5:G15) -> 16014.356 | H4: =SUM(H5:H15) -> 18523.998 | I4: =SUM(I5:I15) -> 18079.07 | J4: =SUM(J5:J15) -> 17686.418 | K4: =SUM(K5:K15) -> 16776.881
A5: Cash and Cash Equivalents | B5: ='INPUT-Y'!F3 -> 68 | C5: ='INPUT-Y'!G3 -> 223 | D5: ='INPUT-Y'!H3 -> 609.4 | E5: ='INPUT-Y'!I3 -> 105.4 | F5: ='INPUT-Y'!J3 -> 135.4 | G5: =CF!G44 -> 624.6134 | H5: =CF!H44 -> 36.557809 | I5: =CF!I44 -> 46.163367 | J5: =CF!J44 -> 154.57385 | K5: =CF!K44 -> 359.25194
A6: Short term financial investment | B6: ='INPUT-Y'!F6 -> 0 | C6: ='INPUT-Y'!G6 -> 8.2 | D6: ='INPUT-Y'!H6 -> 252 | E6: ='INPUT-Y'!I6 -> 12 | F6: ='INPUT-Y'!J6 -> 0 | G6: =F6 -> 0 | H6: =G6 -> 0 | I6: =H6 -> 0 | J6: =I6 -> 0 | K6: =J6 -> 0
A7: Account Receivables | B7: ='INPUT-Y'!F10 -> 257 | C7: ='INPUT-Y'!G10 -> 227.4 | D7: ='INPUT-Y'!H10 -> 245.5 | E7: ='INPUT-Y'!I10 -> 688.2 | F7: ='INPUT-Y'!J10 -> 1434.3 | G7: =G47*IS!G4 -> 957.15038 | H7: =H47*IS!H4 -> 1941.35 | I7: =I47*IS!I4 -> 1839.3806 | J7: =J47*IS!J4 -> 1677.7311 | K7: =K47*IS!K4 -> 1517.8822
A8: Inventory | B8: ='INPUT-Y'!F19 -> 16.2 | C8: ='INPUT-Y'!G19 -> 26.2 | D8: ='INPUT-Y'!H19 -> 24.7 | E8: ='INPUT-Y'!I19 -> 314.3 | F8: ='INPUT-Y'!J19 -> 152 | G8: =-IS!G5*(G52) -> 231.55152 | H8: =-IS!H5*(H52) -> 406.70973 | I8: =-IS!I5*(I52) -> 463.1404 | J8: =-IS!J5*(J52) -> 528.45203 | K8: =-IS!K5*(K52) -> 526.6112
A9: Other Current Assets | B9: ='INPUT-Y'!F22 -> 0.7 | C9: ='INPUT-Y'!G22 -> 1.1 | D9: ='INPUT-Y'!H22 -> 98.2 | E9: ='INPUT-Y'!I22 -> 70.5 | F9: ='INPUT-Y'!J22 -> 57.6 | G9: =AVERAGE(D9:F9) -> 75.433333 | H9: =AVERAGE(E9:G9) -> 67.844444 | I9: =AVERAGE(F9:H9) -> 66.959259 | J9: =AVERAGE(G9:I9) -> 70.079012 | K9: =AVERAGE(H9:J9) -> 68.294239
A10: Tangible Fixed Assets | B10: ='INPUT-Y'!F38 -> 1163.7 | C10: ='INPUT-Y'!G38 -> 1107.4 | D10: ='INPUT-Y'!H38 -> 2871.2 | E10: ='INPUT-Y'!I38 -> 5239.7 | F10: ='INPUT-Y'!J38 -> 5330.2 | G10: ='PP&E'!G8 -> 10111.45 | H10: ='PP&E'!H8 -> 14947.45 | I10: ='PP&E'!I8 -> 13998.45 | J10: ='PP&E'!J8 -> 13049.45 | K10: ='PP&E'!K8 -> 12100.45
A11: Financial leases fixed assets | B11: ='INPUT-Y'!F41 -> 0 | C11: ='INPUT-Y'!G41 -> 0 | D11: ='INPUT-Y'!H41 -> 0 | E11: ='INPUT-Y'!I41 -> 0 | F11: ='INPUT-Y'!J41 -> 27.8 | G11: 27.8 | H11: 27.8 | I11: 27.8 | J11: 27.8 | K11: 27.8
A12: Intangible Fixed Asset | B12: ='INPUT-Y'!F44 -> 5.6 | C12: ='INPUT-Y'!G44 -> 6.6 | D12: ='INPUT-Y'!H44 -> 6.4 | E12: ='INPUT-Y'!I44 -> 19.2 | F12: ='INPUT-Y'!J44 -> 16.7 | G12: ='PP&E'!G44 -> 7.6570313 | H12: ='PP&E'!H44 -> 10.085547 | I12: ='PP&E'!I44 -> 10.97627 | J12: ='PP&E'!J44 -> 12.132251 | K12: ='PP&E'!K44 -> 10.39129
A13: Construction in progress | B13: ='INPUT-Y'!F50 -> 5.6 | C13: ='INPUT-Y'!G50 -> 18 | D13: ='INPUT-Y'!H50 -> 215.8 | E13: ='INPUT-Y'!I50 -> 262.8 | F13: ='INPUT-Y'!J50 -> 541.4 | G13: ='PP&E'!G35 -> 3839.9 | H13: ='PP&E'!H35 -> 947.4 | I13: ='PP&E'!I35 -> 1487.4 | J13: ='PP&E'!J35 -> 2027.4 | K13: ='PP&E'!K35 -> 2027.4
A14: Long term Finacial Investments | B14: ='INPUT-Y'!F53 -> 0.2 | C14: ='INPUT-Y'!G53 -> 0 | D14: ='INPUT-Y'!H53 -> 0 | E14: ='INPUT-Y'!I53 -> 2.6 | F14: ='INPUT-Y'!J53 -> 0 | G14: =87 -> 87 | H14: =G14 -> 87 | I14: =H14 -> 87 | J14: =I14 -> 87 | K14: =J14 -> 87
A15: Other long term assets | B15: ='INPUT-Y'!F59 -> 34 | C15: ='INPUT-Y'!G59 -> 29.8 | D15: ='INPUT-Y'!H59 -> 36.5 | E15: ='INPUT-Y'!I59 -> 47.9 | F15: ='INPUT-Y'!J59 -> 51.8 | G15: =F15 -> 51.8 | H15: =G15 -> 51.8 | I15: =H15 -> 51.8 | J15: =I15 -> 51.8 | K15: =J15 -> 51.8
A17: LIABILITIES | B17: ='INPUT-Y'!F66 -> 401 | C17: ='INPUT-Y'!G66 -> 340.6 | D17: ='INPUT-Y'!H66 -> 1952.6 | E17: ='INPUT-Y'!I66 -> 4183.6 | F17: ='INPUT-Y'!J66 -> 4305.2 | G17: =SUM(G18:G23) -> 11874.588 | H17: =SUM(H18:H23) -> 13907.156 | I17: =SUM(I18:I23) -> 12837.723 | J17: =SUM(J18:J23) -> 11905.551 | K17: =SUM(K18:K23) -> 10436.556
A18: Account Payables | B18: ='INPUT-Y'!F67-'INPUT-Y'!F77 -> 89.9 | C18: ='INPUT-Y'!G67-'INPUT-Y'!G77 -> 97.5 | D18: ='INPUT-Y'!H67-'INPUT-Y'!H77 -> 421.8 | E18: ='INPUT-Y'!I67-'INPUT-Y'!I77 -> 282.8 | F18: ='INPUT-Y'!J67-'INPUT-Y'!J77 -> 500.2 | G18: 2500 | H18: =-IS!H5*H57 -> 2800.2076 | I18: =-IS!I5*I57 -> 2271.4104 | J18: =-IS!J5*J57 -> 1840.9041 | K18: =-IS!K5*K57 -> 1492.677
A19: Short-term borrowings | B19: ='INPUT-Y'!F77 -> 45.2 | C19: ='INPUT-Y'!G77 -> 5.9 | D19: ='INPUT-Y'!H77 -> 106.4 | E19: ='INPUT-Y'!I77 -> 553.6 | F19: ='INPUT-Y'!J77 -> 600.9 | G19: =G64 -> 660.99 | H19: =H64 -> 727.089 | I19: =I64 -> 799.7979 | J19: =J64 -> 879.77769 | K19: =K64 -> 967.75546
A20: Other long-term payables | B20: ='INPUT-Y'!F83+'INPUT-Y'!F88+ 'INPUT-Y'!F94 -> 0.5 | C20: ='INPUT-Y'!G83+'INPUT-Y'!G88+ 'INPUT-Y'!G94 -> 3.9 | D20: ='INPUT-Y'!H83+'INPUT-Y'!H88+ 'INPUT-Y'!H94 -> 3.6 | E20: ='INPUT-Y'!I83+'INPUT-Y'!I88+ 'INPUT-Y'!I94 -> 3.5 | F20: ='INPUT-Y'!J83+'INPUT-Y'!J88+ 'INPUT-Y'!J94 -> 3.2 | G20: =F20 -> 3.2 | H20: =G20 -> 3.2 | I20: =H20 -> 3.2 | J20: =I20 -> 3.2 | K20: =J20 -> 3.2
A21: Long-term borrowings | B21: ='INPUT-Y'!F90 -> 264.5 | C21: ='INPUT-Y'!G90 -> 232.4 | D21: ='INPUT-Y'!H90 -> 1420.3 | E21: ='INPUT-Y'!I90 -> 3343.1 | F21: ='INPUT-Y'!J90 -> 3200.6 | G21: =Debt!J52/1000000 -> 8672.3132 | H21: =Debt!K52/1000000 -> 10336.701 | I21: =Debt!L52/1000000 -> 9721.388 | J21: =Debt!M52/1000000 -> 9137.6753 | K21: =Debt!N52/1000000 -> 7926.7605
A22: Bonus and welfare funds | B22: ='INPUT-Y'!F79 -> 13.6 | C22: ='INPUT-Y'!G79 -> 17.3 | D22: ='INPUT-Y'!H79 -> 20.8 | E22: ='INPUT-Y'!I79 -> 31.6 | F22: ='INPUT-Y'!J79 -> 35.7 | G22: =F22*1.05 -> 37.485 | H22: =G22*1.05 -> 39.35925 | I22: =H22*1.05 -> 41.327213 | J22: =I22*1.05 -> 43.393573 | K22: =J22*1.05 -> 45.563252
A23: Technology-science development fund | B23: ='INPUT-Y'!F95 -> 0.9 | C23: ='INPUT-Y'!G95 -> 0.9 | D23: ='INPUT-Y'!H95 -> 0.6 | E23: ='INPUT-Y'!I95 -> 0.6 | F23: ='INPUT-Y'!J95 -> 0.3 | G23: =$E$23 -> 0.6 | H23: =$E$23 -> 0.6 | I23: =$E$23 -> 0.6 | J23: =$E$23 -> 0.6 | K23: =$E$23 -> 0.6
A25: OWNERS EQUITY | B25: ='INPUT-Y'!F96 -> 1150.7 | C25: ='INPUT-Y'!G96 -> 1318 | D25: ='INPUT-Y'!H96 -> 2408 | E25: ='INPUT-Y'!I96 -> 2579.6 | F25: ='INPUT-Y'!J96 -> 3467.9 | G25: =SUM(G26:G33) -> 4139.7675 | H25: =SUM(H26:H33) -> 4616.8411 | I25: =SUM(I26:I33) -> 5241.3464 | J25: =SUM(J26:J33) -> 5780.8675 | K25: =SUM(K26:K33) -> 6340.3246
A26: Common stock | B26: ='INPUT-Y'!F99 -> 744.9 | C26: ='INPUT-Y'!G99 -> 970.9 | D26: ='INPUT-Y'!H99 -> 1941.8 | E26: ='INPUT-Y'!I99 -> 2038.9 | F26: ='INPUT-Y'!J99 -> 2711.8 | G26: 3037 | H26: =G26 -> 3037 | I26: =H26 -> 3037 | J26: =I26 -> 3037 | K26: =J26 -> 3037
A27: Share premium | B27: ='INPUT-Y'!F101 -> 2 | C27: ='INPUT-Y'!G101 -> 28.9 | D27: ='INPUT-Y'!H101 -> 29 | E27: ='INPUT-Y'!I101 -> 38.7 | F27: ='INPUT-Y'!J101 -> 38.2 | G27: =F27 -> 38.2 | H27: =G27 -> 38.2 | I27: =H27 -> 38.2 | J27: =I27 -> 38.2 | K27: =J27 -> 38.2
A28: Other capitals of Owners Equity | B28: ='INPUT-Y'!F103 -> 0 | C28: ='INPUT-Y'!G103 -> 0 | D28: ='INPUT-Y'!H103 -> 0 | E28: ='INPUT-Y'!I103 -> 0 | F28: ='INPUT-Y'!J103 -> 0 | G28: =F28 -> 0 | H28: =G28 -> 0 | I28: =H28 -> 0 | J28: =I28 -> 0 | K28: =J28 -> 0
A29: Treasury stock | B29: ='INPUT-Y'!F104 -> 0 | C29: ='INPUT-Y'!G104 -> 0 | D29: ='INPUT-Y'!H104 -> 0 | E29: ='INPUT-Y'!I104 -> 0 | F29: ='INPUT-Y'!J104 -> 0 | G29: =F29 -> 0 | H29: =G29 -> 0 | I29: =H29 -> 0 | J29: =I29 -> 0 | K29: =J29 -> 0
A30: Development and Investment Fund | B30: ='INPUT-Y'!F107 -> 49.1 | C30: ='INPUT-Y'!G107 -> 56.3 | D30: ='INPUT-Y'!H107 -> 61 | E30: ='INPUT-Y'!I107 -> 78.8 | F30: ='INPUT-Y'!J107 -> 87.3 | G30: =F30*1.05 -> 91.665 | H30: =G30*1.05 -> 96.24825 | I30: =H30*1.05 -> 101.06066 | J30: =I30*1.05 -> 106.1137 | K30: =J30*1.05 -> 111.41938
A31: Retained earnings | B31: ='INPUT-Y'!F110 -> 168.4 | C31: ='INPUT-Y'!G110 -> 120 | D31: ='INPUT-Y'!H110 -> 145.1 | E31: ='INPUT-Y'!I110 -> 164.8 | F31: ='INPUT-Y'!J110 -> 220 | G31: ='Owners equity'!G29 -> 559.964 | H31: ='Owners equity'!H29 -> 978.71116 | I31: ='Owners equity'!I29 -> 1496.0891 | J31: ='Owners equity'!J29 -> 2027.3186 | K31: ='Owners equity'!K29 -> 2577.2871
A32: Minority interest | B32: ='INPUT-Y'!F114 -> 186.4 | C32: ='INPUT-Y'!G114 -> 141.8 | D32: ='INPUT-Y'!H114 -> 231.1 | E32: ='INPUT-Y'!I114 -> 258.5 | F32: ='INPUT-Y'!J114 -> 410.7 | G32: =(0.5*G73*IS!G18)+F32 -> 412.8825 | H32: =(0.5*H73*IS!H18)+G32 -> 415.17413 | I32: =(0.5*I73*IS!I18)+H32 -> 417.58033 | J32: =(0.5*J73*IS!J18)+I32 -> 420.10685 | K32: =(0.5*K73*IS!K18)+J32 -> 422.75969
A33: Forecasting Discrepancies | G33: =-SUM(G26:G32)-SUM(G18:G23)+SUM(G5:G15) -> 0.055957917 | H33: =-SUM(H26:H32)-SUM(H18:H23)+SUM(H5:H15) -> 51.507571 | I33: =-SUM(I26:I32)-SUM(I18:I23)+SUM(I5:I15) -> 151.41634 | J33: =-SUM(J26:J32)-SUM(J18:J23)+SUM(J5:J15) -> 152.12842 | K33: =-SUM(K26:K32)-SUM(K18:K23)+SUM(K5:K15) -> 153.65846
A34: Balance check | B34: =SUM(B25,B17)-B4 -> 0 | C34: =SUM(C25,C17)-C4 -> 0 | D34: =SUM(D25,D17)-D4 -> 0 | E34: =SUM(E25,E17)-E4 -> 0 | F34: =SUM(F25,F17)-F4 -> 0 | G34: =SUM(G25,G17)-G4 -> 0 | H34: =SUM(H25,H17)-H4 -> 0 | I34: =SUM(I25,I17)-I4 -> 0 | ... K34: =SUM(K25,K17)-K4 -> 0
A44: WORKING CAPITAL
A46: Account receivable
A47: Account receivable/Net revenue | C47: =AVERAGE(B7:C7)/IS!C4 -> 0.4492673 | D47: =AVERAGE(C7:D7)/IS!D4 -> 0.42260947 | E47: =AVERAGE(D7:E7)/IS!E4 -> 0.40266517 | F47: =AVERAGE(E7:F7)/IS!F4 -> 0.71010371 | G47: =F47-5% -> 0.66010371 | H47: =G47-5% -> 0.61010371 | I47: =H47-5% -> 0.56010371 | J47: =I47-5% -> 0.51010371 | K47: =J47-5% -> 0.46010371
A48: Receivable turnover | C48: =IS!C4/AVERAGE(B7:C7) -> 2.2258464 | D48: =IS!D4/AVERAGE(C7:D7) -> 2.3662508 | E48: =IS!E4/AVERAGE(D7:E7) -> 2.4834529 | F48: =IS!F4/AVERAGE(E7:F7) -> 1.408245 | G48: =1/G47 -> 1.5149135 | H48: =1/H47 -> 1.6390656 | I48: =1/I47 -> 1.7853836 | J48: =1/J47 -> 1.9603856 | K48: =1/K47 -> 2.173423
A49: Days of sales outstanding (DSO) | C49: =365/C48 -> 163.98256 | D49: =365/D48 -> 154.25246 | E49: =365/E48 -> 146.97279 | F49: =365/F48 -> 259.18786 | G49: =360/G48 -> 237.63734 | H49: =360/H48 -> 219.63734 | I49: =360/I48 -> 201.63734 | J49: =360/J48 -> 183.63734 | K49: =360/K48 -> 165.63734
A51: Inventory
A52: Inventory/COGS | C52: =AVERAGE(B8:C8)/-IS!C5 -> 0.093268808 | D52: =AVERAGE(C8:D8)/-IS!D5 -> 0.10039448 | E52: =AVERAGE(D8:E8)/-IS!E5 -> 0.33254856 | F52: =AVERAGE(E8:F8)/-IS!F5 -> 0.31820663 | G52: =$F$52+5% -> 0.36820663 | H52: =AVERAGE(C52:G52) -> 0.24252502 | I52: =AVERAGE(D52:H52) -> 0.27237626 | J52: =AVERAGE(E52:I52) -> 0.30677262 | K52: =AVERAGE(F52:J52) -> 0.30161743
A53: Inventory turnover | C53: =-IS!C5/AVERAGE(B8:C8) -> 10.721698 | D53: =-IS!D5/AVERAGE(C8:D8) -> 9.9607073 | E53: =-IS!E5/AVERAGE(D8:E8) -> 3.0070796 | F53: =-IS!F5/AVERAGE(E8:F8) -> 3.1426121 | G53: =1/G52 -> 2.7158663 | H53: =1/H52 -> 4.1232859 | I53: =1/I52 -> 3.6713919 | J53: =1/J52 -> 3.2597433 | K53: =1/K52 -> 3.3154582
A54: Days of inventory on hand (DOH) | C54: =360/C53 -> 33.576771 | D54: =360/D53 -> 36.142012 | E54: =360/E53 -> 119.71748 | F54: =360/F53 -> 114.55439 | G54: =360/G53 -> 132.55439 | H54: =360/H53 -> 87.309008 | I54: =360/I53 -> 98.055455 | J54: =360/J53 -> 110.43814 | K54: =360/K53 -> 108.58228
...

Sheet CF
B1: 2016 | C1: 2017 | D1: 2018 | E1: 2019 | F1: 2020 | G1: 2021F | H1: 2022F | I1: 2023F | J1: 2024F | K1: 2025F
A2: CASH FLOW STATEMENT | B2: HISTORICAL | G2: FORECAST
A4: I. CASH FLOWS FROM OPERATING ACTIVITIES (INDIRECT MEHOD)
A5: Total profit before tax | B5: ='INPUT-Y'!F145 -> 149.2 | C5: ='INPUT-Y'!G145 -> 230.4 | D5: ='INPUT-Y'!H145 -> 206.9 | E5: ='INPUT-Y'!I145 -> 303.9 | F5: ='INPUT-Y'!J145 -> 308.6 | G5: =IS!G15 -> 368.1773 | H5: =IS!H15 -> 450.85716 | I5: =IS!I15 -> 556.93861 | J5: =IS!J15 -> 556.85026 | K5: =IS!K15 -> 579.51292
A6: Adjustments | B6: ='INPUT-Y'!F146 -> 0 | C6: ='INPUT-Y'!G146 -> 0 | D6: ='INPUT-Y'!H146 -> 0 | E6: ='INPUT-Y'!I146 -> 0 | F6: ='INPUT-Y'!J146 -> 0
A7: 1. Depreciation of Fixed Assets Expenses | B7: ='INPUT-Y'!F147 -> 79.8 | C7: ='INPUT-Y'!G147 -> 79.5 | D7: ='INPUT-Y'!H147 -> 97.5 | E7: ='INPUT-Y'!I147 -> 285 | F7: ='INPUT-Y'!J147 -> 354 | G7: =Forecast!G120 -> 349.75 | H7: =Forecast!H120 -> 969 | I7: =Forecast!I120 -> 969 | J7: =Forecast!J120 -> 969 | K7: =Forecast!K120 -> 969
A8: 2. Provisions | B8: ='INPUT-Y'!F148 -> 0 | C8: ='INPUT-Y'!G148 -> 0.3 | D8: ='INPUT-Y'!H148 -> 0.3 | E8: ='INPUT-Y'!I148 -> 0.5 | F8: ='INPUT-Y'!J148 -> -0.4
A9: 3. Unrealised foreign exchange gain/(loss) | B9: ='INPUT-Y'!F150 -> 0 | C9: ='INPUT-Y'!G150 -> 0 | D9: ='INPUT-Y'!H150 -> 0.8 | E9: ='INPUT-Y'!I150 -> 0.5 | F9: ='INPUT-Y'!J150 -> 1.4 | G9: =F9 -> 1.4 | H9: =G9 -> 1.4 | I9: =H9 -> 1.4 | J9: =I9 -> 1.4 | K9: =J9 -> 1.4
A10: 4. Profit/(loss) from liquidating fixed assets | B10: ='INPUT-Y'!F151 -> 0 | C10: ='INPUT-Y'!G151 -> 0 | D10: ='INPUT-Y'!H151 -> 0 | E10: ='INPUT-Y'!I151 -> 0 | F10: ='INPUT-Y'!J151 -> 0
A11: 5. Interest Expenses | B11: ='INPUT-Y'!F152 -> 39.1 | C11: ='INPUT-Y'!G152 -> 24.4 | D11: ='INPUT-Y'!H152 -> 40.2 | E11: ='INPUT-Y'!I152 -> 247.3 | F11: ='INPUT-Y'!J152 -> 357.9 | G11: =-IS!G9 -> 327.34458 | H11: =-IS!H9 -> 798.87064 | I11: =-IS!I9 -> 768.63812 | J11: =-IS!J9 -> 738.40559 | K11: =-IS!K9 -> 708.17306
A12: 6. Other deductions | B12: ='INPUT-Y'!F153 -> 0.9 | C12: ='INPUT-Y'!G153 -> 0 | D12: ='INPUT-Y'!H153 -> 0 | E12: ='INPUT-Y'!I153 -> 0 | F12: ='INPUT-Y'!J153 -> 0
A13: Operating profit/(loss) before changes in Working Capital | B13: ='INPUT-Y'!F157 -> 242 | C13: ='INPUT-Y'!G157 -> 323.5 | D13: ='INPUT-Y'!H157 -> 326.6 | E13: ='INPUT-Y'!I157 -> 813.5 | F13: ='INPUT-Y'!J157 -> 995.7 | G13: =SUM(G5:G11) -> 1046.6719 | H13: =SUM(H5:H11) -> 2220.1278 | I13: =SUM(I5:I11) -> 2295.9767 | J13: =SUM(J5:J11) -> 2265.6559 | K13: =SUM(K5:K11) -> 2258.086
A14: Other adjustments | B14: ='INPUT-Y'!F158 -> -11.2 | C14: ='INPUT-Y'!G158 -> -18.1 | D14: ='INPUT-Y'!H158 -> -95.2 | E14: ='INPUT-Y'!I158 -> -295.7 | F14: ='INPUT-Y'!J158 -> -667.3 | G14: =-(BS!G7-BS!F7) -> 477.14962 | H14: =-(BS!H7-BS!G7) -> -984.19963 | I14: =-(BS!I7-BS!H7) -> 101.96942 | J14: =-(BS!J7-BS!I7) -> 161.64948 | K14: =-(BS!K7-BS!J7) -> 159.84896
A15: 1. (Increase)/decrease in receivables | B15: ='INPUT-Y'!F160 -> -5.9 | C15: ='INPUT-Y'!G160 -> -10 | D15: ='INPUT-Y'!H160 -> 0.8 | E15: ='INPUT-Y'!I160 -> -289.4 | F15: ='INPUT-Y'!J160 -> 161.8 | G15: =-(BS!G8-BS!F8) -> -79.55152 | H15: =-(BS!H8-BS!G8) -> -175.15821 | I15: =-(BS!I8-BS!H8) -> -56.430668 | J15: =-(BS!J8-BS!I8) -> -65.311638 | K15: =-(BS!K8-BS!J8) -> 1.8408355
A16: 2. (Increase)/decrease in inventories | B16: ='INPUT-Y'!F161 -> 10 | C16: ='INPUT-Y'!G161 -> 3.1 | D16: ='INPUT-Y'!H161 -> 7.7 | E16: ='INPUT-Y'!I161 -> -282.4 | F16: ='INPUT-Y'!J161 -> 324.8 | G16: =BS!G18-BS!F18 -> 1999.8 | H16: =BS!H18-BS!G18 -> 300.20761 | I16: =BS!I18-BS!H18 -> -528.79719 | J16: =BS!J18-BS!I18 -> -430.50628 | K16: =BS!K18-BS!J18 -> -348.22716
A17: 3. Increase/(decrease) in payables | B17: =-('INPUT-Y'!F22-'INPUT-Y'!E22) -> 4.4 | C17: =-('INPUT-Y'!G22-'INPUT-Y'!F22) -> -0.4 | D17: =-('INPUT-Y'!H22-'INPUT-Y'!G22) -> -97.1 | E17: =-('INPUT-Y'!I22-'INPUT-Y'!H22) -> 27.7 | F17: =-('INPUT-Y'!J22-'INPUT-Y'!I22) -> 12.9 | G17: =BS!G9-BS!F9 -> 17.833333 | H17: =BS!H9-BS!G9 -> -7.5888889 | I17: =BS!I9-BS!H9 -> -0.88518519 | J17: =BS!J9-BS!I9 -> 3.1197531 | K17: =BS!K9-BS!J9 -> -1.7847737
A18: 6. Interest paid | B18: ='INPUT-Y'!F163 -> -42.6 | C18: ='INPUT-Y'!G163 -> -31.3 | D18: ='INPUT-Y'!H163 -> -50.1 | E18: ='INPUT-Y'!I163 -> -246.7 | F18: ='INPUT-Y'!J163 -> -356.2 | G18: =IS!G9 + 74 -> -253.34458 | H18: =IS!H9 - 19 -> -817.87064 | I18: =IS!I9 - 32 -> -800.63812 | J18: =IS!J9 - 39 -> -777.40559 | K18: =IS!K9 - 25 -> -733.17306
A19: 7. Income Tax paid | B19: ='INPUT-Y'!F164 -> -19.4 | C19: ='INPUT-Y'!G164 -> -16.9 | D19: ='INPUT-Y'!H164 -> -25.8 | E19: ='INPUT-Y'!I164 -> -13 | F19: ='INPUT-Y'!J164 -> -11.3 | G19: =IS!G16 -> -27.613297 | H19: =IS!H16 -> -31.560001 | I19: =IS!I16 -> -38.985702 | J19: =IS!J16 -> -25.058262 | K19: =IS!K16 -> -28.975646
A20: 8. Other Incomes from Operating Activities | B20: ='INPUT-Y'!F165 -> 0 | C20: ='INPUT-Y'!G165 -> 0 | D20: ='INPUT-Y'!H165 -> 0 | E20: ='INPUT-Y'!I165 -> 0 | F20: ='INPUT-Y'!J165 -> 0
A21: 9. Other Expenses from Operating Activities | B21: ='INPUT-Y'!F166 -> -6.4 | C21: ='INPUT-Y'!G166 -> -10.9 | D21: ='INPUT-Y'!H166 -> -12.3 | E21: ='INPUT-Y'!I166 -> -5.9 | F21: ='INPUT-Y'!J166 -> -18.4
A22: Net cashflow from operating activities | B22: ='INPUT-Y'!F144 -> 168.4 | C22: ='INPUT-Y'!G144 -> 243.8 | D22: ='INPUT-Y'!H144 -> 141.1 | E22: ='INPUT-Y'!I144 -> -332.8 | F22: ='INPUT-Y'!J144 -> 420.6 | G22: =SUM(G13:G19) -> 3180.9454 | H22: =SUM(H13:H19) -> 503.95804 | I22: =SUM(I13:I19) -> 972.20928 | J22: =SUM(J13:J19) -> 1132.1433 | K22: =SUM(K13:K19) -> 1307.6151
A24: II. CASH FLOWS FROM INVESTING ACTIVITIES
A25: 1. Purchases of fixed assets and other long term assets | B25: ='INPUT-Y'!F168 -> -40.5 | C25: ='INPUT-Y'!G168 -> -46.8 | D25: ='INPUT-Y'!H168 -> -1810 | E25: ='INPUT-Y'!I168 -> -2667.7 | F25: ='INPUT-Y'!J168 -> -779.3 | G25: =-(BS!G15-BS!F15-'PP&E'!G6+'PP&E'!G30+'PP&E'!G41) -> -8389.5 | H25: =-(BS!H15-BS!G15-'PP&E'!H6+'PP&E'!H30+'PP&E'!H41) -> -2872.5 | I25: =-(BS!I15-BS!H15-'PP&E'!I6+'PP&E'!I30+'PP&E'!I41) -> -520 | J25: =-(BS!J15-BS!I15-'PP&E'!J6+'PP&E'!J30+'PP&E'!J41) -> -520 | K25: =-(BS!K15-BS!J15-'PP&E'!K6+'PP&E'!K30+'PP&E'!K41) -> 20
A26: 2. Proceeds from disposal of fixed assets | B26: ='INPUT-Y'!F169 -> 0.9 | C26: ='INPUT-Y'!G169 -> 2.7 | D26: ='INPUT-Y'!H169 -> 0.2 | E26: ='INPUT-Y'!I169 -> 2.8 | F26: ='INPUT-Y'!J169 -> 32.1
A27: 3. Changes in ST-LT Financial Investments | B27: =-('INPUT-Y'!F6+'INPUT-Y'!F53-'INPUT-Y'!E53-'INPUT-Y'!E6) -> 0.7 | C27: =-('INPUT-Y'!G6+'INPUT-Y'!G53-'INPUT-Y'!F53-'INPUT-Y'!F6) -> -8 | D27: =-('INPUT-Y'!H6+'INPUT-Y'!H53-'INPUT-Y'!G53-'INPUT-Y'!G6) -> -243.8 | E27: =-('INPUT-Y'!I6+'INPUT-Y'!I53-'INPUT-Y'!H53-'INPUT-Y'!H6) -> 237.4 | F27: =-('INPUT-Y'!J6+'INPUT-Y'!J53-'INPUT-Y'!I53-'INPUT-Y'!I6) -> 14.6 | G27: =- ((BS!G6-BS!F6)+(BS!G14-BS!F14)) -> -87 | H27: =- ((BS!H6-BS!G6)+(BS!H14-BS!G14)) -> 0 | I27: =- ((BS!I6-BS!H6)+(BS!I14-BS!H14)) -> 0 | J27: =- ((BS!J6-BS!I6)+(BS!J14-BS!I14)) -> 0 | K27: =- ((BS!K6-BS!J6)+(BS!K14-BS!J14)) -> 0
A28: 4. Interest, dividends, shared profit from investments | B28: ='INPUT-Y'!F174 -> 15.7 | C28: ='INPUT-Y'!G174 -> 21.4 | D28: ='INPUT-Y'!H174 -> 13.9 | E28: ='INPUT-Y'!I174 -> 22.7 | F28: ='INPUT-Y'!J174 -> 20.4 | G28: 14
A29: 5. Changes in other LT assets | B29: ='INPUT-Y'!F167 - SUM(B25:B28) -> 114.1 | C29: ='INPUT-Y'!G167 - SUM(C25:C28) -> 35.3 | D29: ='INPUT-Y'!H167 - SUM(D25:D28) -> 93.8 | E29: ='INPUT-Y'!I167 - SUM(E25:E28) -> -237.3 | F29: ='INPUT-Y'!J167 - SUM(F25:F28) -> -225
A30: Net Cash flow from Investing activities | B30: ='INPUT-Y'!F167 -> 90.9 | C30: ='INPUT-Y'!G167 -> 4.6 | D30: ='INPUT-Y'!H167 -> -1945.9 | E30: ='INPUT-Y'!I167 -> -2642.1 | F30: ='INPUT-Y'!J167 -> -937.2 | G30: =SUM(G25:G29) -> -8462.5 | H30: =SUM(H25:H29) -> -2872.5 | I30: =SUM(I25:I29) -> -520 | J30: =SUM(J25:J29) -> -520 | K30: =SUM(K25:K29) -> 20
A32: III. CASH FLOWS FROM FINANCING ACTIVITIES
A33: Proceeds from issue of shares | B33: ='INPUT-Y'!F177 -> 0 | C33: ='INPUT-Y'!G177 -> 1 | D33: ='INPUT-Y'!H177 -> 1049.8 | E33: ='INPUT-Y'!I177 -> 270.3 | F33: ='INPUT-Y'!J177 -> 673.3 | G33: =BS!G26-BS!F26 -> 325.2 | H33: =BS!H26-BS!G26 -> 0 | I33: =BS!I26-BS!H26 -> 0 | J33: =BS!J26-BS!I26 -> 0 | K33: =BS!K26-BS!J26 -> 0
A34: Payments for share returns and repurchases | B34: ='INPUT-Y'!F104-'INPUT-Y'!E104 -> 0 | C34: ='INPUT-Y'!G104-'INPUT-Y'!F104 -> 0 | D34: ='INPUT-Y'!H104-'INPUT-Y'!G104 -> 0 | E34: ='INPUT-Y'!I104-'INPUT-Y'!H104 -> 0 | F34: ='INPUT-Y'!J104-'INPUT-Y'!I104 -> 0
A35: Increase / (Pay-off) of ST loans | B35: ='INPUT-Y'!F77-'INPUT-Y'!E77 -> -57.3 | C35: =BS!C19-BS!B19 -> -39.3 | D35: =BS!D19-BS!C19 -> 100.5 | E35: =BS!E19-BS!D19 -> 447.2 | F35: =BS!F19-BS!E19 -> 47.3 | G35: =BS!G19-BS!F19 -> 60.09 | H35: =BS!H19-BS!G19 -> 66.099 | I35: =BS!I19-BS!H19 -> 72.7089 | J35: =BS!J19-BS!I19 -> 79.97979 | K35: =BS!K19-BS!J19 -> 87.977769
A36: Increase / (Pay-off) of LT loans | B36: ='INPUT-Y'!F90-'INPUT-Y'!E90 -> -253 | C36: =BS!C21-BS!B21 -> -32.1 | D36: =BS!D21-BS!C21 -> 1187.9 | E36: =BS!E21-BS!D21 -> 1922.8 | F36: =BS!F21-BS!E21 -> -142.5 | G36: =BS!G21-BS!F21 -> 5471.7132 | H36: =BS!H21-BS!G21 -> 1664.3874 | I36: =BS!I21-BS!H21 -> -615.31262 | J36: =BS!J21-BS!I21 -> -583.71262 | K36: =BS!K21-BS!J21 -> -1210.9148
A37: Dividends paid | B37: ='INPUT-Y'!F182 -> -39.5 | C37: ='INPUT-Y'!G182 -> -29.5 | D37: ='INPUT-Y'!H182 -> -150.7 | E37: ='INPUT-Y'!I182 -> -166.9 | F37: ='INPUT-Y'!J182 -> -35.6 | G37: =-'Owners equity'!G30 -> -86.23524 | H37: =-'Owners equity'!H30 -> 0 | I37: =-'Owners equity'!I30 -> 0 | J37: =-'Owners equity'!J30 -> 0 | K37: =-'Owners equity'!K30 -> 0
A38: Changes in other LT liabilities | B38: =-('INPUT-Y'!F82-'INPUT-Y'!F90)-('INPUT-Y'!E82-'INPUT-Y'!E90)-('INPUT-Y'!F94-'INPUT-Y'!E94) -> -1.9 | C38: =-('INPUT-Y'!G82-'INPUT-Y'!G90)-('INPUT-Y'!F82-'INPUT-Y'!F90)-('INPUT-Y'!G94-'INPUT-Y'!F94) -> -9.7 | D38: =-('INPUT-Y'!H82-'INPUT-Y'!H90)-('INPUT-Y'!G82-'INPUT-Y'!G90)-('INPUT-Y'!H94-'INPUT-Y'!G94) -> -8.9 | E38: =-('INPUT-Y'!I82-'INPUT-Y'!I90)-('INPUT-Y'!H82-'INPUT-Y'!H90)-('INPUT-Y'!I94-'INPUT-Y'!H94) -> -8.2 | F38: =-('INPUT-Y'!J82-'INPUT-Y'!J90)-('INPUT-Y'!I82-'INPUT-Y'!I90)-('INPUT-Y'!J94-'INPUT-Y'!I94) -> -7.3
A39: Other distribution from equity | B39: ='INPUT-Y'!F176 - SUM(B33:B38) -> 71.7 | C39: ='INPUT-Y'!G176 - SUM(C33:C38) -> 16.2 | D39: ='INPUT-Y'!H176 - SUM(D33:D38) -> 12.6 | E39: ='INPUT-Y'!I176 - SUM(E33:E38) -> 5.9 | F39: ='INPUT-Y'!J176 - SUM(F33:F38) -> 11.5
A40: Net Cashflow from Financing activities | B40: ='INPUT-Y'!F176 -> -280 | C40: ='INPUT-Y'!G176 -> -93.4 | D40: ='INPUT-Y'!H176 -> 2191.2 | E40: ='INPUT-Y'!I176 -> 2471.1 | F40: ='INPUT-Y'!J176 -> 546.7 | G40: =SUM(G33:G39) -> 5770.768 | H40: =SUM(H33:H39) -> 1730.4864 | I40: =SUM(I33:I39) -> -542.60372 | J40: =SUM(J33:J39) -> -503.73283 | K40: =SUM(K33:K39) -> -1122.937
A42: Net Cash and Cash equivalents during the period | B42: ='INPUT-Y'!F184 -> -20.7 | C42: ='INPUT-Y'!G184 -> 155 | D42: ='INPUT-Y'!H184 -> 386.4 | E42: ='INPUT-Y'!I184 -> -503.7 | F42: ='INPUT-Y'!J184 -> 30.1 | G42: =SUM(G40,G30,G22) -> 489.2134 | H42: =SUM(H40,H30,H22) -> -638.05559 | I42: =SUM(I40,I30,I22) -> -90.394442 | J42: =SUM(J40,J30,J22) -> 108.41048 | K42: =SUM(K40,K30,K22) -> 204.67809
A43: Cash and cash equivalents at beginning of year | B43: ='INPUT-Y'!F185 -> 88.7 | C43: =B44 -> 68 | D43: =C44 -> 223 | E43: =D44 -> 609.4 | F43: =E44 -> 105.4 | G43: =F44 -> 135.4 | H43: =G44+50 -> 674.6134 | I43: =H44+100 -> 136.55781 | J43: =I44 -> 46.163367 | K43: =J44 -> 154.57385
A44: Cash and Cash equivalents at end of year | B44: ='INPUT-Y'!F186 -> 68 | C44: ='INPUT-Y'!G186 -> 223 | D44: ='INPUT-Y'!H186 -> 609.4 | E44: ='INPUT-Y'!I186 -> 105.4 | F44: ='INPUT-Y'!J186 -> 135.4 | G44: =SUM(G42:G43) -> 624.6134 | H44: =SUM(H42:H43) -> 36.557809 | I44: =SUM(I42:I43) -> 46.163367 | J44: =SUM(J42:J43) -> 154.57385 | K44: =SUM(K42:K43) -> 359.25194

Sheet Valuation
A1: VALUATION SUMMARY | F1: WACC
A2: Valuation Date: | B2: 44545 | F2: Beta | G2: =WACC!H2 -> 0.74372848
A3: Company Name: | B3: GEC | F3: Risk free rate | G3: =WACC!H3 -> 0.037
A4: Share Price: | B4: 20.28 | F4: Premium | G4: =WACC!H4 -> 0.0821
A5: Basic Shares Outstanding (mil shares): | B5: 303.715 | F5: D | G5: =WACC!H5 -> 0.57223053
F6: E | G6: =WACC!H6 -> 0.42776947
F7: Marginal tax rate | G7: =WACC!H7 -> 0.07
F8: Cost of equity | G8: =WACC!H8 -> 0.098060108
F9: Cost of debt | G9: =WACC!H9 -> 0.09
F10: WACC | G10: =WACC!H10 -> 0.089842816
A14: MUTIPLE METHOD
A15: P/E
A16: COMPANY | B16: COUNTRY | C16: Market capitalisation | D16: ROE (TTM) | E16: ROA (TTM) | F16: P/B (Q) | G16: P/E (TTM)
A17: SAHACOGEN CHONBURI | B17: Thailand | C17: 3286 | D17: 0.093 | E17: 0.062 | F17: 10.75 | G17: 26.8
A18: GEPIC ENERGY | B18: Chinese | C18: 11291.5 | D18: 0.066 | E18: 0.026 | F18: 14.33 | G18: 19.5
A19: Guizhou Qianyu | B19: Chinese | C19: 21787 | D19: 0.143 | E19: 0.026 | F19: 3.4 | G19: 15.4
A20: Guangzhou Heng | B20: Chinese | C20: 20500 | D20: 0.077 | E20: 0.031 | F20: 1.3 | G20: 14.1
A21: PetroVietnam Power Nhon Trach 2 JSC | B21: Vietnam | C21: 7456 | D21: 0.15 | E21: 0.091 | F21: 1.8 | G21: 12.1
A22: Vinh Son - Song Hinh Hydropower JSC | B22: Vietnam | C22: 6803 | D22: 0.102 | E22: 0.037 | F22: 1.8 | G22: 19.1
A23: Power Generation Joint Stock Corporation 2 | B23: Vietnam | C23: 36786 | D23: N/A | E23: N/A | F23: 1.8 | G23: 21.7
A24: PetroVietnam Power Corporation | B24: Vietnam | C24: 40046 | D24: 0.096 | E24: 0.054 | F24: 1.2 | G24: 14.7
A25: MEDIAN | C25: =MEDIAN(C17:C24) -> 15895.75 | D25: =MEDIAN(D17:D24) -> 0.096 | E25: =MEDIAN(E17:E24) -> 0.037 | F25: =MEDIAN(F21:F24) -> 1.8 | G25: =MEDIAN(G17:G24) -> 17.25
A26: GIA LAI ELECTRICITY JSC (GEG) | B26: Vietnam | C26: 5937 | D26: 0.096 | E26: 0.031 | F26: 1.7 | G26: 22.8
A28: EPS | B28: =IS!G18/B5 -> 1.119352
A29: P/E | B29: =G25 -> 17.25
A30: Target Price ( 1000 VNĐ) | B30: =B28*B29 -> 19.308822
A36: FCFF PROJECTION | B36: 2021F | C36: 2022F | D36: 2023F | E36: 2024F | F36: 2025F
A37: Operating profit | B37: =IS!G6+IS!G10+IS!G11 -> 670.32375 | C37: =IS!H6+IS!H10+IS!H11 -> 1210.0945 | D37: =IS!I6+IS!I10+IS!I11 -> 1283.3494 | E37: =IS!J6+IS!J10+IS!J11 -> 1250.4932 | F37: =IS!K6+IS!K10+IS!K11 -> 1244.9523
A38: Tax | B38: =IS!G16+IS!G17 -> -28.213297 | C38: =IS!H16+IS!H17 -> -32.110001 | D38: =IS!I16+IS!I17 -> -39.560702 | E38: =IS!J16+IS!J17 -> -25.620762 | F38: =IS!K16+IS!K17 -> -29.544396
A39: Depreciation | B39: =CF!G7 -> 349.75 | C39: =CF!H7 -> 969 | D39: =CF!I7 -> 969 | E39: =CF!J7 -> 969 | F39: =CF!K7 -> 969
A40: Change in net working capital | B40: =SUM(CF!I8:I10,CF!I14:I16) -> -481.85844 | C40: =SUM(CF!J8:J10,CF!J14:J16) -> -332.76844 | D40: =SUM(CF!K8:K10,CF!K14:K16) -> -185.13736 | E40: =SUM(CF!L8:L10,CF!L14:L16) -> 0 | F40: =SUM(CF!M8:M10,CF!M14:M16) -> 0
A41: Capex | B41: =CF!G25 -> -8389.5 | C41: =CF!H25 -> -2872.5 | D41: =CF!I25 -> -520 | E41: =CF!J25 -> -520 | F41: =CF!K25 -> 20
A42: FCFF | B42: =SUM(B37:B41) -> -7879.498 | C42: =SUM(C37:C41) -> -1058.2839 | D42: =SUM(D37:D41) -> 1507.6513 | E42: =SUM(E37:E41) -> 1673.8725 | F42: =SUM(F37:F41) -> 2204.4079
A43: WACC | B43: =G10 -> 0.089842816
A44: Mid Point | B44: =1/12 -> 0.083333333 | C44: =1+B44 -> 1.0833333 | D44: =1+C44 -> 2.0833333 | E44: =1+D44 -> 3.0833333 | F44: =1+E44 -> 4.0833333
A45: Discount Factor | B45: =1/(1+$B$43)^B44 -> 0.99285618 | C45: =1/(1+$B$43)^C44 -> 0.9110086 | D45: =1/(1+$B$43)^D44 -> 0.83590825 | E45: =1/(1+$B$43)^E44 -> 0.76699891 | F45: =1/(1+$B$43)^F44 -> 0.70377021
A46: Present value of FCFF | B46: =B45*B42 -> -7823.2083 | C46: =C45*C42 -> -964.10578 | D46: =D45*D42 -> 1260.2582 | E46: =E45*E42 -> 1283.8584 | F46: =F45*F42 -> 1551.3966
A49: Enterprise Value (MillionVND) | D49: Implied Enterprise Value and Share Price
A50: Cumulative Present Value of FCFF | B50: =SUM(B46:F46) -> -4691.8009 | D50: Enterprise Value | F50: =B60 -> 11253.479
D51: Less: Total Debt | F51: =BS!F19+BS!F21 -> 3801.5
...

Sheet PP&E
A1: PROPERTY, PLANT, AND EQUIPMENT (PP&E)
B2: 2016 | C2: 2017 | D2: 2018 | E2: 2019 | F2: 2020 | G2: 2021 | H2: 2022 | I2: 2023 | J2: 2024 | K2: 2025
A3: Tangible Fixed Assets
A4: Beginning of period | C4: =B8 -> 1163.7 | D4: =C8 -> 1107.4 | E4: =D8 -> 2871.2 | F4: =E8 -> 5239.7 | G4: =F8 -> 5330.2 | H4: =G8 -> 10111.45 | I4: =H8 -> 14947.45 | J4: =I8 -> 13998.45 | K4: =J8 -> 13049.45
A5: Plus: Transfer from Construction in progress | F5: =-F31 -> 400.7 | G5: =-G31 -> 5111 | H5: =-H31 -> 5785 | I5: =-I31 -> 0 | J5: =-J31 -> 0 | K5: =-K31 -> 0
A6: Plus: Purchase/Liquidate | F6: =83.4 -35.5-24.2 -> 23.7 | G6: =20 -> 20 | H6: =20 -> 20 | I6: =20 -> 20 | J6: =20 -> 20 | K6: =20 -> 20
A7: Less: Depreciation | B7: =B52 -> 0 | C7: =C52 -> -74 | D7: =D52 -> -95.4 | E7: =E52 -> -277.3 | F7: =F52 -> -333.9 | G7: =G26 -> -349.75 | H7: =H26 -> -969 | I7: =I26 -> -969 | J7: =J26 -> -969 | K7: =AVERAGE(H7:J7) -> -969
A8: End of period | B8: ='INPUT-Y'!F38 -> 1163.7 | C8: ='INPUT-Y'!G38 -> 1107.4 | D8: ='INPUT-Y'!H38 -> 2871.2 | E8: ='INPUT-Y'!I38 -> 5239.7 | F8: =SUM(F4:F7) -> 5330.2 | G8: =SUM(G4:G7) -> 10111.45 | H8: =SUM(H4:H7) -> 14947.45 | I8: =SUM(I4:I7) -> 13998.45 | J8: =SUM(J4:J7) -> 13049.45 | K8: =SUM(K4:K7) -> 12100.45
A9: Fixed assets' average depreciable life | B9: =F84 -> 19.659778
A10: Increase in year | B10: =ROUND(B9,0) -> 20
A11: Charge for every year | B11: =F7 -> -333.9
A12: Acummulated depr. | D12: =D16 -> -622.9 | E12: =E16 -> -900.2 | F12: =F16 -> -1234.1 | G12: =$B$11+F12 -> -1568 | H12: =$B$11+G12 -> -1901.9 | I12: =$B$11+H12 -> -2235.8 | J12: =$B$11+I12 -> -2569.7 | K12: =$B$11+J12 -> -2903.6
A13: Net asset value | D13: =$D$15+D12 -> 2871.2 | E13: =$D$15+E12 -> 2593.9 | F13: =$D$15+F12 -> 2260 | G13: =$D$15+G12 -> 1926.1 | H13: =$D$15+H12 -> 1592.2 | I13: =$D$15+I12 -> 1258.3 | J13: =$D$15+J12 -> 924.4 | K13: =$D$15+K12 -> 590.5
A14: Old tangible assets
A15: Gross tangible assets | C15: =C49 -> 1634.9 | D15: =D49 -> 3494.1 | E15: =E49 -> 6139.9 | F15: =F49 -> 6564.4 | G15: =$F$15 -> 6564.4 | H15: =$F$15 -> 6564.4 | I15: =$F$15 -> 6564.4 | J15: =$F$15 -> 6564.4 | K15: =$F$15 -> 6564.4
A16: Accumulated depreciation | C16: =C51 -> -527.5 | D16: =D51 -> -622.9 | E16: =E51 -> -900.2 | F16: =F51 -> -1234.1 | G16: =F16+G17 -> -1568 | H16: =G16+H17 -> -1971.9 | I16: =H16+I17 -> -2375.8 | J16: =I16+J17 -> -2779.7 | K16: =J16+K17 -> -3183.6
A17: Depreciation from old tangible assets | C17: =C7 -> -74 | D17: =D7 -> -95.4 | E17: =E7 -> -277.3 | F17: =F7 -> -333.9 | G17: =IF(AND(G13<0,F13<0),0,IF(AND(G13<0,F13>0),-(G$15+F$12),$B$11)) -> -333.9 | H17: =IF(AND(H13<0,G13<0),0,IF(AND(H13<0,G13>0),-(H$15+G$12),$B$11-70)) -> -403.9 | I17: =IF(AND(I13<0,H13<0),0,IF(AND(I13<0,H13>0),-(I$15+H$12),$B$11-70)) -> -403.9 | J17: =IF(AND(J13<0,I13<0),0,IF(AND(J13<0,I13>0),-(J$15+I$12),$B$11-70)) -> -403.9 | K17: =IF(AND(K13<0,J13<0),0,IF(AND(K13<0,J13>0),-(K$15+J$12),$B$11-70)) -> -403.9
A19: Depreciation from new tangible assets
A20: Tan Phu Dong 2 wind farm | G20: =-SLN(2242,0,$B$10)+110 -> -2.1 | H20: =-SLN(2242,0,$B$10) -> -112.1 | I20: =-SLN(2242,0,$B$10) -> -112.1 | J20: =-SLN(2242,0,$B$10) -> -112.1 | K20: =-SLN(2242,0,$B$10) -> -112.1
A21: VPL1 wind farm | G21: =-SLN(1320,0,$B$10)+60 -> -6 | H21: =-SLN(1320,0,$B$10) -> -66 | I21: =-SLN(1320,0,$B$10) -> -66 | J21: =-SLN(1320,0,$B$10) -> -66 | K21: =-SLN(1320,0,$B$10) -> -66
A22: IA Bang 1 wind farm | G22: =-SLN(1955,0,$B$10)+90 -> -7.75 | H22: =-SLN(1955,0,$B$10) -> -97.75 | I22: =-SLN(1955,0,$B$10) -> -97.75 | J22: =-SLN(1955,0,$B$10) -> -97.75 | K22: =-SLN(1955,0,$B$10) -> -97.75
A23: Tan Phu Dong 1 wind farm | H23: =-SLN(4465,0,$B$10) -> -223.25 | I23: =-SLN(4465,0,$B$10) -> -223.25 | J23: =-SLN(4465,0,$B$10) -> -223.25 | K23: =-SLN(4465,0,$B$10) -> -223.25
A24: VPL2 wind farm | H24: =-SLN(1320,0,$B$10) -> -66 | I24: =-SLN(1320,0,$B$10) -> -66 | J24: =-SLN(1320,0,$B$10) -> -66 | K24: =-SLN(1320,0,$B$10) -> -66
A25: Total depreciation from new CAPEX | G25: =SUM(G20:G24) -> -15.85 | H25: =SUM(H20:H24) -> -565.1 | I25: =SUM(I20:I24) -> -565.1 | J25: =SUM(J20:J24) -> -565.1 | K25: =SUM(K20:K24) -> -565.1
A26: Total tangible assets depreciation | G26: =G17+G25 -> -349.75 | H26: =H17+H25 -> -969 | I26: =I17+I25 -> -969 | J26: =J17+J25 -> -969 | K26: =K17+K25 -> -969
A28: Construction in progress (all)
A29: Beginning balance | C29: =B35 -> 5.6 | D29: =C35 -> 18 | E29: =D35 -> 215.8 | F29: =E35 -> 262.8 | G29: =F35 -> 541.4 | H29: =G35 -> 3839.9 | I29: =H35 -> 947.4 | J29: =I35 -> 1487.4 | K29: =J35 -> 2027.4
A30: New construction at the beginning of the year | F30: 675.3 | G30: =5517+5785/2 -> 8409.5 | H30: =2892.5 -> 2892.5 | I30: 540 | J30: 540
A31: Transfer to tangible fixed assets (enter as -) | F31: -400.7 | G31: -5111 | H31: =-5785 -> -5785 | J31: 0 | K31: 0
A32: Transfer to intangible fixed assets (enter as -) | F32: -0.7 | J32: 0 | K32: 0
A33: Transfer to investment properties (enter as -) | J33: 0 | K33: 0
A34: Other changes | F34: =6.3-0.2-1.4 -> 4.7 | J34: 0 | K34: 0
A35: Ending balance | B35: ='INPUT-Y'!F52 -> 5.6 | C35: ='INPUT-Y'!G52 -> 18 | D35: ='INPUT-Y'!H52 -> 215.8 | E35: ='INPUT-Y'!I52 -> 262.8 | F35: =SUM(F29:F34) -> 541.4 | G35: =SUM(G29:G31) -> 3839.9 | H35: =SUM(H29:H31) -> 947.4 | I35: =SUM(I29:I31) -> 1487.4 | J35: =SUM(J29:J31) -> 2027.4 | K35: =SUM(K29:K31) -> 2027.4
A37: Intangible fixed assets
A38: Beginning balance | C38: =B44 -> 5.6 | D38: =C44 -> 6.6 | E38: =D44 -> 6.4 | F38: =E44 -> 19.2 | G38: =F44 -> 16.7 | H38: =G44 -> 7.6570313 | I38: =H44 -> 10.085547 | J38: =I44 -> 10.97627 | K38: =J44 -> 12.132251
A39: - Original price | B39: ='INPUT-Y'!E45 -> 6.2 | C39: ='INPUT-Y'!F45 -> 6.4 | D39: ='INPUT-Y'!G45 -> 7.5 | E39: ='INPUT-Y'!H45 -> 7.4 | F39: ='INPUT-Y'!I45 -> 21.1 | G39: =AVERAGE(C39:F39) -> 10.6 | H39: =AVERAGE(D39:G39) -> 11.65 | I39: =AVERAGE(E39:H39) -> 12.6875 | J39: =AVERAGE(F39:I39) -> 14.009375 | K39: =AVERAGE(G39:J39) -> 12.236719
A40: - % Amortization/Intangible assets | C40: =-C43/C38 -> 0.035714286 | D40: =-D43/D38 -> 0.015151515 | E40: =-E43/E38 -> 0.140625 | F40: =-F43/F38 -> 0.140625 | G40: =F40 -> 0.140625 | H40: =G40 -> 0.140625 | I40: =H40 -> 0.140625 | J40: =I40 -> 0.140625 | K40: =J40 -> 0.140625
A41: - Purchases of intangible assets | C41: =C60 -> 1.1 | D41: =D60 -> -0.1 | E41: =E60 -> 13.7 | F41: =F60 -> 0.2 | G41: 0 | H41: 0 | I41: 0 | J41: 0 | K41: 0
A42: - Accumulated depreciation | B42: =B61 -> -0.7 | C42: =C61 -> -0.9 | D42: =D61 -> -1 | E42: =E61 -> -1.9 | F42: =F61 -> -4.6 | G42: =G40*-AVERAGE(SUM(F39,F41),SUM(G39,G41))+F32 -> -2.9429687 | H42: =H40*-AVERAGE(SUM(G39,G41),SUM(H39,H41))+G32 -> -1.5644531 | I42: =I40*-AVERAGE(SUM(H39,H41),SUM(I39,I41))+H32 -> -1.7112305 | J42: =J40*-AVERAGE(SUM(I39,I41),SUM(J39,J41))+I32 -> -1.877124 | K42: =K40*-AVERAGE(SUM(J39,J41),SUM(K39,K41))+J32 -> -1.8454285
A43: Gain/(loss) in depreciation | B43: -0.2 | C43: =C42-B42 -> -0.2 | D43: =D42-C42 -> -0.1 | E43: =E42-D42 -> -0.9 | F43: =F42-E42 -> -2.7 | G43: =G42-F42 -> 1.6570313 | H43: =H42-G42 -> 1.3785156 | I43: =I42-H42 -> -0.14677734 | J43: =J42-I42 -> -0.16589355 | K43: =K42-J42 -> 0.031695557
...

Sheet Assumption
A1: CÔNG TY CỔ PHẦN ĐIỆN GIA LAI - GIA LAI ELECTRICITY JOINT STOCK COMPANY BẢNG GIẢ ĐỊNH - ASSUMPTION
B3: Income Statement Assumptions
A4: Solar power | B4: Solar radiation falling on Vietnam is forecasted to increase sharply in the coming years, especially in the Central and Southern regions. GEG is developing a team of experienced technicians to run factories better. EVN will upgrade the power transmission line to meet the electricity output according to Circular 55. Therefore, we forecast that the actual output divided by theory (Qr/Q) of the solar power array will be 105% from 2023 onward. Duc Hue 1-Long An solar power plant alone will be 115% from 2023 because the demand for electricity in the South and heat radiation in this area will increase sharply. In the two years 2021 and 2022, due to the complicated situation of the Covid epidemic, we have set the Qr/Q level at 90% and 100% respectively.
A6: Wind power | B6: In 2021, 3 wind power plants will officially come into operation and enjoy preferential FIT prices: Ia Bang 1, Tan Phu Dong 2 and VPL1-Ben Tre. In which, Ia Bang 1 is an onshore project, so the FIT price is 8.5 cents/kwh; Tan Phu Dong 2 and VPL1 are nearshore projects, so the FIT price 9.8 iscents/kwh. We forecast that the output of these 3 factories will be 16% compared to the average output in 2021 (Since these factories will come into operation in Q4/2021 when the epidemic situation is under control, industrial zones are gradually reopening, leading to a recovery in electricity demand) and 100% for the following years due to GEG's improvement in operating quality, EVN's upgrade of power transmission lines and favorable location in strong wind area. The remaining 2 plants, VPL2-Tien Giang and Tan Phu Dong 1 (2 projects near the shore) are still waiting to finalize electricity prices. According to the company's forecast, the price is expected to decrease by 10% compared to the nearshore FIT price.
A8: Hydroeclectricity | B8: For the hydropower segment, we forecast to operate at a Qr/Q (real volume/average volume) level of 90% in 2021 due to La Nina and down to 80% in 2022 and 77% onward due to the phenomenon La Nina phasing out.
A10: Construction | B10: We forecast that revenue from this segment will account for 5% in 2021 due to the COVID-19 pandemic; and maintained at 5% onward as the GEG is focusing on the renewable energy segment.
A12: Gross Profit Margin | B12: We expect gross profit margin to grow at a CAGR of 13% from 2021-2025. In which, gross profit margin will decrease to 47% in the period 2021-2022 due to the sharp increase in depreciation expense from new factories.
A14: COGS | B14: We forecast material cost will increase 2% per year due to inflation. Labor costs in 2021 decreased sharply due to GEG's personnel restructuring. Previously, in 2019 when GEG carried out the construction of solar power plants, it also restructured once. That's why we set the 2021 labor cost at 10 VND/kwh. The following years is 100 VND/kwh We estimate the cost of outsourcing will decrease by 10% per year from 2021 as GEG is upgrading the in-house technician team to maintain the factories without having to outsource them.
B17: Balance Sheet Assumptions
A18: Day Receivable/Revenue | B18: 5% reduction (compared to the previous year) from 2021 onward due to the implementation of TPD1, VPL2 projects by enterprises.
A20: DOH/Revenue | B20: Increase 5% point in 2021 (according to the company's expected data) and we take the average of 5 previous years for the next forecast
A22: Long-term Debt | B22: Besides assuming the company will gradually repay its debt in the future, we believe that the company will add about VND 2 trillion in long-term debt in 2022 to finance 2 wind power projects VPL2 and Tan Phu Dong 1 in Tien Giang (Total investment is about 5 trillion, 70% financed by debt, about 3.5 trillion, in 2021, 1.5 trillion has been disbursed)
A24: Short-term Debt | B24: Increase 10% each year
A26: %Cash Dividend | B26: GEG is in the investment phase so we expect the cash dividend to drop to 3% per year

Sheet Forecast
A1: FORECAST | B1: 2016 | C1: 2017 | D1: 2018 | E1: 2019 | F1: 2020 | G1: 2021F | H1: 2022F | I1: 2023F | J1: 2024F | K1: 2025F | O1: Sản lượng bình quân của mảng điện mặt trời
A3: Solar Energy
A4: Phong Điền-Huế | O4: 2016 | P4: 2017 | Q4: 2018 | R4: 2019 | S4: 2020 | T4: 2021F | U4: 2022F | V4: 2023F | W4: 2024F | X4: 2025F
A5: Average volume (Q) | E5: 60 | F5: 60 | G5: 60 | H5: 60 | I5: 60 | J5: 60 | K5: 60 | N5: Solar energy revenue | Q5: 37.3 | R5: 678 | S5: 895 | T5: 827 | U5: 942 | V5: 987 | W5: 987 | X5: 987
A6: As percentage (%) of total volume | E6: =E5/$P$19 -> 0.14814815 | F6: =F5/$P$19 -> 0.14814815 | G6: =G5/$P$19 -> 0.14814815 | H6: =H5/$P$19 -> 0.14814815 | I6: =I5/$P$19 -> 0.14814815 | J6: =J5/$P$19 -> 0.14814815 | K6: =K5/$P$19 -> 0.14814815 | N6: Average volume | Q6: 23.6 | R6: 272 | S6: 405 | T6: 405 | U6: 405 | V6: 405 | W6: 405 | X6: 405
A7: Real vloumne (Qr) | E7: 68 | F7: =58.52 -> 58.52 | G7: =G5*G8 -> 54 | H7: =H5*H8 -> 60 | I7: =I5*I8 -> 63 | J7: =J5*J8 -> 63 | K7: =K5*K8 -> 63 | N7: Real volume (Qr) | Q7: 17.7 | R7: 315 | S7: 395 | T7: 364.5 | U7: 415.01 | V7: 434.9 | W7: 434.9 | X7: 434.9
A8: Qr/Q | E8: =E7/E5 -> 1.1333333 | F8: =F7/F5 -> 0.97533333 | G8: =90% -> 0.9 | H8: =100% -> 1 | I8: 1.05 | J8: 1.05 | K8: 1.05
A9: FIT price | E9: =E10/E7 -> 2.1764706 | F9: =$F$10/$F$7 -> 2.2940875 | G9: =$F$10/$F$7 -> 2.2940875 | H9: =$F$10/$F$7 -> 2.2940875 | I9: =$F$10/$F$7 -> 2.2940875 | J9: =$F$10/$F$7 -> 2.2940875 | K9: =$F$10/$F$7 -> 2.2940875
A10: Revenue (YTD) | E10: =148 -> 148 | F10: =15%*S5 -> 134.25 | G10: =G9*G7 -> 123.88072 | H10: =H9*H7 -> 137.64525 | I10: =I9*I7 -> 144.52751 | J10: =J9*J7 -> 144.52751 | K10: =K9*K7 -> 144.52751 | N10: Wind power revenue | T10: 142 | U10: 1686 | V10: 1704 | W10: 1704 | X10: 1704
A11: As percentage (%) of solar revenue | E11: =E10/$S$5 -> 0.16536313 | F11: =F10/$S$5 -> 0.15 | G11: =G10/T5 -> 0.14979531 | H11: =H10/U5 -> 0.14612022 | I11: =I10/V5 -> 0.14643112 | J11: =J10/W5 -> 0.14643112 | K11: =K10/X5 -> 0.14643112 | N11: Average volume | T11: 66 | U11: 806.9 | V11: 814.6 | W11: 814.6 | X11: 814.6
N12: Real volume (Qr) | T12: 66 | U12: 806.9 | V12: 814.6 | W12: 814.6 | X12: 814.6
A13: Krong Pa-Gia Lai
A14: Average volume (Q) | E14: 103 | F14: 103 | G14: 103 | H14: 103 | I14: 103 | J14: 103 | K14: 103 | N14: Hydroelectric revenue | P14: 484 | Q14: 446 | R14: 380 | S14: 396 | T14: 409 | U14: 391 | V14: 427 | W14: 433 | X14: 440
A15: As percentage (%) of total volume | E15: =E14/R6 -> 0.37867647 | F15: =$F$14/$S$6 -> 0.25432099 | G15: =$F$14/$S$6 -> 0.25432099 | H15: =$F$14/$S$6 -> 0.25432099 | I15: =$F$14/$S$6 -> 0.25432099 | J15: =$F$14/$S$6 -> 0.25432099 | K15: =$F$14/$S$6 -> 0.25432099 | N15: Average volume | P15: 367 | Q15: 367 | R15: 367 | S15: 367 | T15: 367 | U15: 367 | V15: 367 | W15: 367 | X15: 367
A16: Real vloumne (Qr) | E16: 105 | F16: =F15*S7 -> 100.45679 | G16: =G17*G14 -> 92.7 | H16: =H17*H14 -> 103 | I16: =I17*I14 -> 108.15 | J16: =J17*J14 -> 108.15 | K16: =K17*K14 -> 108.15 | N16: Real volume (Qr) | P16: 426 | Q16: 363 | R16: 278 | S16: 321 | T16: 321 | U16: 307 | V16: 316 | W16: 314 | X16: 312
A17: Qr/Q | E17: =E16/E14 -> 1.0194175 | F17: =F16/F14 -> 0.97530864 | G17: =90% -> 0.9 | H17: =100% -> 1 | I17: 1.05 | J17: 1.05 | K17: 1.05
A18: FIT price | E18: =226/E16 -> 2.152381 | F18: =$F$19/$F$16 -> 2.2658228 | G18: =$F$19/$F$16 -> 2.2658228 | H18: =$F$19/$F$16 -> 2.2658228 | I18: =$F$19/$F$16 -> 2.2658228 | J18: =$F$19/$F$16 -> 2.2658228 | K18: =$F$19/$F$16 -> 2.2658228 | N18: Total revenue | O18: 431.4 | P18: 539.1 | Q18: 559.5 | R18: 1159.4 | S18: 1493.3 | T18: 1450 | U18: 3182 | V18: 3284 | W18: 3289 | X18: 3299
A19: Revenue (YTD) | E19: 226 | F19: =F15*S5 -> 227.61728 | G19: =G18*G16 -> 210.04177 | H19: =H18*H16 -> 233.37975 | I19: =I18*I16 -> 245.04873 | J19: =J18*J16 -> 245.04873 | K19: =K18*K16 -> 245.04873 | N19: Total solar energy volume in 2020 (MWp) | P19: 405
A20: As percentage (%) of solar revenue | E20: =E19/R5 -> 0.33333333 | F20: =F19/S5 -> 0.25432099 | G20: =G15 -> 0.25432099 | H20: =H15 -> 0.25432099 | I20: =I15 -> 0.25432099 | J20: =J15 -> 0.25432099 | K20: =K15 -> 0.25432099
A22: Đức Huệ 1-Long An
A23: Average volume (Q) | E23: =73*0.5 -> 36.5 | F23: =E23*2 -> 73 | G23: =73 -> 73 | H23: =73 -> 73 | I23: =73 -> 73 | J23: =73 -> 73 | K23: =73 -> 73
A24: As percentage (%) of total volume | E24: =E23/R6 -> 0.13419118 | F24: =$F$23/$S$6 -> 0.18024691 | G24: =$F$23/$S$6 -> 0.18024691 | H24: =$F$23/$S$6 -> 0.18024691 | I24: =$F$23/$S$6 -> 0.18024691 | J24: =$F$23/$S$6 -> 0.18024691 | K24: =$F$23/$S$6 -> 0.18024691
A25: Real vloumne (Qr) | E25: 52 | F25: =F24*S7 -> 71.197531 | G25: =G26*G23 -> 65.7 | H25: =H26*H23 -> 83.95 | I25: =I26*I23 -> 83.95 | J25: =J26*J23 -> 83.95 | K25: =K26*K23 -> 83.95
A26: Qr/Q | E26: =E25/E23 -> 1.4246575 | F26: =F25/F23 -> 0.97530864 | G26: =0.9 -> 0.9 | H26: =100%+15% -> 1.15 | I26: =100%+15% -> 1.15 | J26: =100%+15% -> 1.15 | K26: =100%+15% -> 1.15
A27: FIT price | E27: =E28/E25 -> 2.1730769 | F27: =$F$28/$F$25 -> 2.2658228 | G27: =$F$28/$F$25 -> 2.2658228 | H27: =$F$28/$F$25 -> 2.2658228 | I27: =$F$28/$F$25 -> 2.2658228 | J27: =$F$28/$F$25 -> 2.2658228 | K27: =$F$28/$F$25 -> 2.2658228
A28: Revenue (YTD) | E28: =113 -> 113 | F28: =F24*S5 -> 161.32099 | G28: =G27*G25 -> 148.86456 | H28: =H27*H25 -> 190.21582 | I28: =I27*I25 -> 190.21582 | J28: =J27*J25 -> 190.21582 | K28: =K27*K25 -> 190.21582
A29: As percentage (%) of solar revenue | E29: =E28/R5 -> 0.16666667 | F29: =F28/S5 -> 0.18024691 | G29: =G24 -> 0.18024691 | H29: =H24 -> 0.18024691 | I29: =I24 -> 0.18024691 | J29: =J24 -> 0.18024691 | K29: =K24 -> 0.18024691
A31: Hàm Phú 2-Bình Thuận
A32: Average volume (Q) | E32: =77/2 -> 38.5 | F32: =77 -> 77 | G32: =77 -> 77 | H32: =77 -> 77 | I32: =77 -> 77 | J32: =77 -> 77 | K32: =77 -> 77
