Workbook

Sheet Assumption Summary
B2: Assumptions Control Sheet
B4: Income Statement | C4: Assumptions
B5: Market Penetration
B6: Commercial vehicles-Dieslel+Petrol | C6: Increase 900 bps in 2022 and stay unchanged due to: - Indian construction sector recovery - Competition from other players (Suzuki, Huyndai)
B7: Commercial vehicles-EV | C7: Stays unchanged due to: - Tata Motors is focusing on PV-EV - Cost to build and operate an e-bus is twice as much as the normal one - Infrastructure is not apt for e-vehicles to operate
B8: Passenger vehicles-Diesel+Petrol | C8: Increase to 15% in 2023 and stays unchanged due to: - Competition from the second largest player-Huyndai - Demand recovers modestly, however inflation is surging up
B9: Passenger vehicles-EV | C9: Increase modestly by 100 bps each year until 2023 due to: - Tata Motors' current penatration is at its peak - Big players (Maruti, Huyndai) enter the market since 2023
B10: JLR-Diesel+Petrol | C10: Stays unchanged until 2023 and decrease 200 bps till 2026: - Luxury car segment is expected to recover post COVID-19 - In the long run, affluent candidates will adopt to new EV mode
B11: JLR-EV | C11: Increase modestly to 8.8% in 2023 and stay unchanged: - Tata Motors' plan on converting Jaguar 100% electrified - But the shortage of semiconducts and higher input material may cause production to slow down
B12: Tata Motors' production capacity
B13: Commercial vehicles-Dieslel+Petrol | C13: -Production recover 14% in 2022F calculated by the booking orders announced by Tata Motors -Production increase slow down to 12% afterward due to inflation
B14: Commercial vehicles-EV | C14: -Increase 30% per annum due to Government's plan on zero carbon emission in 2040
B15: Passenger vehicles-Diesel+Petrol | C15: -Production increase modestly 1.7% per annum due to fierce competition
B16: Passenger vehicles-EV | C16: -Production increase 12% per annum for Tata Motors to meet its plan
B17: JLR-Diesel+Petrol | C17: -Production increase 9% per annum beacause luxury car segment is on the track of recovery to the pre COVID-19 production
B18: JLR-EV | C18: -Production increase 30% per annum beacause luxury EV car segment is expanding rapidly in the short run
B19: Other Income statement' s elements
B20: Average COGS as Percentage of Revenue | C20: =AVERAGE('Income Statement'!B5:F5)/AVERAGE('Income Statement'!B4:F4)+2% -> 0.61902928
B21: Research and Development increase 10% each year due to Tata Motors' plan on expanding its EV business | C21: 0.1
B22: Sales, General and administrative increase 7% each year due to inflation | C22: 0.07
B23: Other operating expenses as Percentage of Revenue | C23: =AVERAGE('Income Statement'!B10:F10)/AVERAGE('Income Statement'!B4:F4) -> 0.032681238
B24: Other income (net) as percentage of Revenue | C24: =AVERAGE('Income Statement'!B14:F14)/AVERAGE('Income Statement'!B4:F4) -> 0.0083848713
B25: Provision for income tax as percentage of Revenue | C25: =AVERAGE('Income Statement'!B16:F16)/AVERAGE('Income Statement'!B4:F4) -> 0.0061495066
B27: Balance Sheet
B28: Asset side
B29: Goodwill stay unchanged | C29: 0
B30: Long Term Investments as percentage of revenue | C30: =AVERAGE('Balance Sheet'!B19:F19)/AVERAGE('Income Statement'!B4:F4) -> 0.095016738
B31: Gross property, plant and equipment increases 2% per year because Tata Motors decrease their spending on factories to reach their "Net Zero Debt" plan | C31: 0.02
B32: Intangible assets as Percentage of Revenue+2% because of Tata new model of EVs every 2 years requires, patents, copyrights,… | C32: =AVERAGE('Balance Sheet'!B18:F18)/AVERAGE('Income Statement'!B4:F4)+2% -> 0.25312877
B33: Other long-term assets as Percentage of Revenue | C33: =AVERAGE('Balance Sheet'!B20:F20)/AVERAGE('Income Statement'!B4:F4) -> 0.038744927
B34: Liabilities and Equity side
B35: Minority interest as percentage of revenue | C35: =AVERAGE('Balance Sheet'!B34:F34)/AVERAGE('Income Statement'!B4:F4) -> 0.0055575103
B36: Short Term Debt increase 2% | C36: 0.02
B37: Long Term Debt increase 2% as a portion of PP&E | C37: 0.02
B38: Other long-term liabilities as Percentage of Revenue | C38: =AVERAGE('Balance Sheet'!B35:F35)/AVERAGE('Income Statement'!B4:F4) -> 0.097412055
B39: Common stock stay unchanged | C39: 0
B40: Additional paid-in capital stay unchanged | C40: 0
B41: Accumulated other comprehensive income as Percentage of Revenue | C41: =AVERAGE('Balance Sheet'!B42:F42)/AVERAGE('Income Statement'!B4:F4) -> 0.048568215
B42: Corporate Tax Rate | C42: 0.3
B45: Interest rate
...

Sheet Revenue forecast
A1: Market Penetration | B1: 2021 | C1: 2022F | D1: 2023F | E1: 2024F | F1: 2025F | G1: 2026F
A2: Commercial vehicles-Dieslel+Petrol | B2: 0.42 | C2: 0.51 | D2: 0.51 | E2: 0.51 | F2: 0.51 | G2: 0.51
A3: Commercial vehicles-EV | B3: 0.35 | C3: 0.35 | D3: 0.35 | E3: 0.35 | F3: 0.35 | G3: 0.35
A4: Passenger vehicles-Diesel+Petrol | B4: 0.1 | C4: 0.141 | D4: 0.145 | E4: 0.15 | F4: 0.15 | G4: 0.15
A5: Passenger vehicles-EV | B5: 0.87 | C5: 0.88 | D5: 0.89 | E5: 0.9 | F5: 0.9 | G5: 0.9
A6: JLR-Diesel+Petrol | B6: 0.05 | C6: 0.05 | D6: 0.05 | E6: 0.048 | F6: 0.048 | G6: 0.048
A7: JLR-EV | B7: 0.086 | C7: 0.086 | D7: 0.088 | E7: 0.088 | F7: 0.088 | G7: 0.088
A9: Tata Motors' production capacity | B9: Average selling price1 | C9: TAM units in segment2 | H9: Max units Tata | M9: Estimated revenue per segment1
C10: 2022F3 | D10: 2023F | E10: 2024F | F10: 2025F | G10: 2026F | H10: 2022F | I10: 2023F | J10: 2024F | K10: 2025F | L10: 2026F | M10: 2022F | N10: 2023F | O10: 2024F | P10: 2025F | Q10: 2026F
A11: Commercial vehicles-Dieslel+Petrol | B11: 3 | C11: 600000 | D11: =C11*1.14 -> 684000 | E11: =D11*1.12 -> 766080 | F11: =E11*1.12 -> 858009.6 | G11: =F11*1.12 -> 960970.75 | H11: =C11*'Revenue forecast'!C2 -> 306000 | I11: =D11*'Revenue forecast'!D2 -> 348840 | J11: =E11*'Revenue forecast'!E2 -> 390700.8 | K11: =F11*'Revenue forecast'!F2 -> 437584.9 | L11: =G11*'Revenue forecast'!G2 -> 490095.08 | M11: =$B11*H11 -> 918000 | N11: =$B11*I11 -> 1046520 | O11: =$B11*J11 -> 1172102.4 | P11: =$B11*K11 -> 1312754.7 | Q11: =$B11*L11 -> 1470285.3
A12: Commercial vehicles-EV | B12: 1.4 | C12: 700 | D12: =C12*1.3 -> 910 | E12: =D12*1.3 -> 1183 | F12: =E12*1.3 -> 1537.9 | G12: =F12*1.3 -> 1999.27 | H12: =C12*'Revenue forecast'!C5 -> 616 | I12: =D12*'Revenue forecast'!D3 -> 318.5 | J12: =E12*'Revenue forecast'!E3 -> 414.05 | K12: =F12*'Revenue forecast'!F3 -> 538.265 | L12: =G12*'Revenue forecast'!G3 -> 699.7445 | M12: =$B12*H12 -> 862.4 | N12: =$B12*I12 -> 445.9 | O12: =$B12*J12 -> 579.67 | P12: =$B12*K12 -> 753.571 | Q12: =$B12*L12 -> 979.6423
A13: Passenger vehicles-Diesel+Petrol | B13: 0.9 | C13: 2666000 | D13: =C13*1.017 -> 2711322 | E13: =D13*1.017 -> 2757414.5 | F13: =E13*1.017 -> 2804290.5 | G13: =F13*1.017 -> 2851963.5 | H13: =C13*'Revenue forecast'!C4 -> 375906 | I13: =D13*'Revenue forecast'!D4 -> 393141.69 | J13: =E13*'Revenue forecast'!E4 -> 413612.17 | K13: =F13*'Revenue forecast'!F4 -> 420643.58 | L13: =G13*'Revenue forecast'!G4 -> 427794.52 | M13: =$B13*H13 -> 338315.4 | N13: =$B13*I13 -> 353827.52 | O13: =$B13*J13 -> 372250.95 | P13: =$B13*K13 -> 378579.22 | Q13: =$B13*L13 -> 385015.07
A14: Passenger vehicles-EV | B14: 5 | C14: 23000 | D14: =C14*1.12 -> 25760 | E14: =D14*1.12 -> 28851.2 | F14: =E14*1.12 -> 32313.344 | G14: =F14*1.12 -> 36190.945 | H14: =C14*'Revenue forecast'!C5 -> 20240 | I14: =D14*'Revenue forecast'!D5 -> 22926.4 | J14: =E14*'Revenue forecast'!E5 -> 25966.08 | K14: =F14*'Revenue forecast'!F5 -> 29082.01 | L14: =G14*'Revenue forecast'!G5 -> 32571.851 | M14: =$B14*H14 -> 101200 | N14: =$B14*I14 -> 114632 | O14: =$B14*J14 -> 129830.4 | P14: =$B14*K14 -> 145410.05 | Q14: =$B14*L14 -> 162859.25
A15: JLR-Diesel+Petrol | B15: 8 | C15: 5685472 | D15: =C15*1.09 -> 6197164.5 | E15: =D15*1.09 -> 6754909.3 | F15: =E15*1.09 -> 7362851.1 | G15: =F15*1.09 -> 8025507.7 | H15: =C15*'Revenue forecast'!C6 -> 284273.6 | I15: =D15*'Revenue forecast'!D6 -> 309858.22 | J15: =E15*'Revenue forecast'!E6 -> 324235.65 | K15: =F15*'Revenue forecast'!F6 -> 353416.85 | L15: =G15*'Revenue forecast'!G6 -> 385224.37 | M15: =$B15*H15 -> 2274188.8 | N15: =$B15*I15 -> 2478865.8 | O15: =$B15*J15 -> 2593885.2 | P15: =$B15*K15 -> 2827334.8 | Q15: =$B15*L15 -> 3081795
A16: JLR-EV | B16: 12 | C16: 304128 | D16: =C16*1.2 -> 364953.6 | E16: =D16*1.2 -> 437944.32 | F16: =E16*1.2 -> 525533.18 | G16: =F16*1.2 -> 630639.82 | H16: =C16*'Revenue forecast'!C7 -> 26155.008 | I16: =D16*'Revenue forecast'!D7 -> 32115.917 | J16: =E16*'Revenue forecast'!E7 -> 38539.1 | K16: =F16*'Revenue forecast'!F7 -> 46246.92 | L16: =G16*'Revenue forecast'!G7 -> 55496.304 | M16: =$B16*H16 -> 313860.1 | N16: =$B16*I16 -> 385391 | O16: =$B16*J16 -> 462469.2 | P16: =$B16*K16 -> 554963.04 | Q16: =$B16*L16 -> 665955.65
A18: (1) Million INR
A19: (2) Total Addressable Market in base year 2021=Tata Motors' capacity in segment 2021/Tata Motors' market share in segment in India 2021
A20: (3) Estimated by using the real data from October-2022 report by Tata Motors, McKinsey, BCG

Sheet NWC
A1: Asset side | B1: 2017 | C1: 2018 | D1: 2019 | E1: 2020 | F1: 2021 | G1: 2022F | H1: 2023F | I1: 2024F | J1: 2025F | K1: 2026F
A2: Account receivable | B2: ='Balance Sheet'!B7 -> 349771 | C2: ='Balance Sheet'!C7 -> 373466 | D2: ='Balance Sheet'!D7 -> 316765 | E2: ='Balance Sheet'!E7 -> 713237 | F2: ='Balance Sheet'!F7 -> 656055 | G2: =(2*'Income Statement'!G4/NWC!G3)-NWC!F2 -> 615356.21 | H2: =(2*'Income Statement'!H4/NWC!H3)-NWC!G2 -> 928817.87 | I2: =(2*'Income Statement'!I4/NWC!I3)-NWC!H2 -> 891020.96 | J2: =(2*'Income Statement'!J4/NWC!J3)-NWC!I2 -> 1083642.4 | K2: =(2*'Income Statement'!K4/NWC!K3)-NWC!J2 -> 979024.58
A3: Receivable turnover | C3: ='Income Statement'!C4/AVERAGE(NWC!B2:C2) -> 8.3496392 | D3: ='Income Statement'!D4/AVERAGE(NWC!C2:D2) -> 7.5646559 | E3: ='Income Statement'!E4/AVERAGE(NWC!D2:E2) -> 4.850375 | F3: ='Income Statement'!F4/AVERAGE(NWC!E2:F2) -> 4.0671179 | G3: =AVERAGE(C3:F3) -> 6.207947 | H3: =AVERAGE(D3:G3) -> 5.672524 | I3: =AVERAGE(E3:H3) -> 5.199491 | J3: =AVERAGE(F3:I3) -> 5.28677 | K3: =AVERAGE(G3:J3) -> 5.591683
A4: Days of sales outstanding (DSO) | C4: =360/C3 -> 43.115636 | D4: =360/D3 -> 47.589739 | E4: =360/E3 -> 74.221065 | F4: =360/F3 -> 88.514769 | G4: =360/G3 -> 57.990186 | H4: =360/H3 -> 63.463813 | I4: =360/I3 -> 69.237547 | J4: =360/J3 -> 68.094508 | K4: =360/K3 -> 64.381332
A6: Inventory | B6: ='Balance Sheet'!B8 -> 443981 | C6: ='Balance Sheet'!C8 -> 401916 | D6: ='Balance Sheet'!D8 -> 382387 | E6: ='Balance Sheet'!E8 -> 376313 | F6: ='Balance Sheet'!F8 -> 367871 | G6: =(2*G7*'Income Statement'!G5)/360 -NWC!F6 -> 567132.3 | H6: =(2*H7*'Income Statement'!H5)/360 -NWC!G6 -> 617468.51 | I6: =(2*I7*'Income Statement'!I5)/360 -NWC!H6 -> 679065.8 | J6: =(2*J7*'Income Statement'!J5)/360 -NWC!I6 -> 736581.23 | K6: =(2*K7*'Income Statement'!K5)/360 -NWC!J6 -> 826402.69
A7: Inventory turnover | C7: =360/('Income Statement'!C5/(AVERAGE(NWC!B6:C6))) -> 82.943999 | D7: =360/('Income Statement'!D5/(AVERAGE(NWC!C6:D6))) -> 91.814509 | E7: =360/('Income Statement'!E5/(AVERAGE(NWC!D6:E6))) -> 91.756582 | F7: =360/('Income Statement'!F5/(AVERAGE(NWC!E6:F6))) -> 78.704794 | G7: 68.892257 | H7: 78.648553 | I7: 79.685915 | J7: 78.861097 | K7: 78.808701
A8: Days of inventory on hand (DOH) | C8: =360/C7 -> 4.3402778 | D8: =360/D7 -> 3.9209489 | E8: =360/E7 -> 3.9234243 | F8: =360/F7 -> 4.5740543 | G8: =360/G7 -> 5.225551 | H8: =360/H7 -> 4.5773252 | I8: =360/I7 -> 4.5177369 | J8: =360/J7 -> 4.5649885 | K8: =360/K7 -> 4.5680235
A10: Prepaid Expenses | B10: ='Balance Sheet'!B9 -> 14404 | C10: ='Balance Sheet'!C9 -> 12107 | D10: ='Balance Sheet'!D9 -> 13344 | E10: ='Balance Sheet'!E9 -> 12201 | F10: ='Balance Sheet'!F9 -> 20293 | G10: ='Income Statement'!G4*NWC!G11 -> 20590.425 | H10: ='Income Statement'!H4*NWC!H11 -> 22850.929 | I10: ='Income Statement'!I4*NWC!I11 -> 24684.539 | J10: ='Income Statement'!J4*NWC!J11 -> 27234.207 | K10: ='Income Statement'!K4*NWC!K11 -> 30088.665
A11: Prepaid Expenses/Revenue | F11: =AVERAGE(B10:F10)/AVERAGE('Income Statement'!B4:F4) -> 0.0052174856 | G11: =F11 -> 0.0052174856 | H11: =G11 -> 0.0052174856 | I11: =H11 -> 0.0052174856 | J11: =I11 -> 0.0052174856 | K11: =J11 -> 0.0052174856
A13: Other Current Assets | B13: ='Balance Sheet'!B10 -> 59178 | C13: ='Balance Sheet'!C10 -> 30185 | D13: ='Balance Sheet'!D10 -> 41789 | E13: ='Balance Sheet'!E10 -> 50125 | F13: ='Balance Sheet'!F10 -> 43967 | G13: =G14*'Income Statement'!G4 -> 64104.128 | H13: =H14*'Income Statement'!H4 -> 71141.752 | I13: =I14*'Income Statement'!I4 -> 76850.327 | J13: =J14*'Income Statement'!J4 -> 84788.205 | K13: =K14*'Income Statement'!K4 -> 93674.981
A14: Other Current Assets/Revenue | F14: =AVERAGE(B13:F13)/AVERAGE('Income Statement'!B4:F4) -> 0.016243588 | G14: =F14 -> 0.016243588 | H14: =G14 -> 0.016243588 | I14: =H14 -> 0.016243588 | J14: =I14 -> 0.016243588 | K14: =J14 -> 0.016243588
A16: Liabilities side | B16: 2017 | C16: 2018 | D16: 2019 | E16: 2020 | F16: 2021 | G16: 2022F | H16: 2023F | I16: 2024F | J16: 2025F | K16: 2026F
A17: Account payable | B17: ='Balance Sheet'!B28 -> 781422 | C17: ='Balance Sheet'!C28 -> 738582 | D17: ='Balance Sheet'!D28 -> 676833 | E17: ='Balance Sheet'!E28 -> 776430 | F17: ='Balance Sheet'!F28 -> 714967 | G17: =(2*'Income Statement'!G5/NWC!G18)-NWC!F17 -> 1060881.7 | H17: =(2*'Income Statement'!H5/NWC!H18)-NWC!G17 -> 1154153 | I17: =(2*'Income Statement'!I5/NWC!I18)-NWC!H17 -> 1270181.4 | J17: =(2*'Income Statement'!J5/NWC!J18)-NWC!I17 -> 1376876.8 | K17: =(2*'Income Statement'!K5/NWC!K18)-NWC!J17 -> 1545680.4
A18: Payables turnover | C18: ='Income Statement'!C5/(AVERAGE(NWC!B17:C17)) -> 2.4154068 | D18: ='Income Statement'!D5/(AVERAGE(NWC!C17:D17)) -> 2.1726575 | E18: ='Income Statement'!E5/(AVERAGE(NWC!D17:E17)) -> 2.0482886 | F18: ='Income Statement'!F5/(AVERAGE(NWC!E17:F17)) -> 2.2823822 | G18: 2.7513084 | H18: 2.4479541 | I18: 2.4160863 | J18: 2.4413564 | K18: 2.4429795
A19: Days payable outstanding (DPO) | C19: =360/C18 -> 149.04322 | D19: =360/D18 -> 165.6957 | E19: =360/E18 -> 175.75648 | F19: =360/F18 -> 157.72994 | G19: =360/G18 -> 130.84684 | H19: =360/H18 -> 147.06158 | I19: =360/I18 -> 149.0013 | J19: =360/J18 -> 147.45901 | K19: =360/K18 -> 147.36104
A21: Deferred tax liabilities | B21: ='Balance Sheet'!B33 -> 61258 | C21: ='Balance Sheet'!C33 -> 14910 | D21: ='Balance Sheet'!D33 -> 19419 | E21: ='Balance Sheet'!E33 -> 15559 | F21: ='Balance Sheet'!F33 -> 15584 | G21: ='Income Statement'!G4*NWC!G22 -> 36067.181 | H21: ='Income Statement'!H4*NWC!H22 -> 40026.79 | I21: ='Income Statement'!I4*NWC!I22 -> 43238.63 | J21: ='Income Statement'!J4*NWC!J22 -> 47704.752 | K21: ='Income Statement'!K4*NWC!K22 -> 52704.757
A22: Deferred tax liabilities/Revenue | F22: =AVERAGE(B21:F21)/AVERAGE('Income Statement'!B4:F4) -> 0.0091391996 | G22: =F22 -> 0.0091391996 | H22: =G22 -> 0.0091391996 | I22: =H22 -> 0.0091391996 | J22: =I22 -> 0.0091391996 | K22: =J22 -> 0.0091391996
A24: Other Current Liabilities | B24: ='Balance Sheet'!B29 -> 482824 | C24: ='Balance Sheet'!C29 -> 514489 | D24: ='Balance Sheet'!D29 -> 564082 | E24: ='Balance Sheet'!E29 -> 584434 | F24: ='Balance Sheet'!F29 -> 618079 | G24: ='Income Statement'!G4*NWC!G25 -> 786604.36 | H24: ='Income Statement'!H4*NWC!H25 -> 872961.14 | I24: ='Income Statement'!I4*NWC!I25 -> 943009.51 | J24: ='Income Statement'!J4*NWC!J25 -> 1040413.1 | K24: ='Income Statement'!K4*NWC!K25 -> 1149460.3
A25: Other Current Liabilities/Revenue | F25: =AVERAGE(B24:F24)/AVERAGE('Income Statement'!B4:F4) -> 0.19932066 | G25: =F25 -> 0.19932066 | H25: =G25 -> 0.19932066 | I25: =H25 -> 0.19932066 | J25: =I25 -> 0.19932066 | K25: =J25 -> 0.19932066

Sheet Income Statement
A1: Income Statement
B2: Historical Values | G2: Forecasted Values
A3: Fiscal year ends in March. INR in millions except per share data. | B3: 2017 | C3: 2018 | D3: 2019 | E3: 2020 | F3: 2021 | G3: 2022F | H3: 2023F | I3: 2024F | J3: 2025F | K3: 2026F
A4: Revenue1 | B4: 2954093 | C4: 3019384 | D4: 2610680 | E4: 2497948 | F4: 2784536 | G4: =SUM('Revenue forecast'!M11:M16) -> 3946426.7 | H4: =SUM('Revenue forecast'!N11:N16) -> 4379682.2 | I4: =SUM('Revenue forecast'!O11:O16) -> 4731117.8 | J4: =SUM('Revenue forecast'!P11:P16) -> 5219795.4 | K4: =SUM('Revenue forecast'!Q11:Q16) -> 5766889.8
A5: Cost of revenue | B5: 1742884 | C5: 1835714 | D5: 1537606 | E5: 1488351 | F5: 1701969 | G5: =G4*'Assumption Summary'!$C$20 -> 2442953.7 | H5: =H4*'Assumption Summary'!$C$20 -> 2711151.5 | I5: =I4*'Assumption Summary'!$C$20 -> 2928700.4 | J5: =J4*'Assumption Summary'!$C$20 -> 3231206.2 | K5: =K4*'Assumption Summary'!$C$20 -> 3569873.7
A6: Gross profit | B6: =B4-B5 -> 1211209 | C6: =C4-C5 -> 1183670 | D6: =D4-D5 -> 1073074 | E6: =E4-E5 -> 1009597 | F6: =F4-F5 -> 1082567 | G6: =G4-G5 -> 1503473 | H6: =H4-H5 -> 1668530.7 | I6: =I4-I5 -> 1802417.3 | ... K6: =K4-K5 -> 2197016.2
A7: Operating expenses
A8: Research and Development | B8: 250855 | C8: 278152 | D8: 256139 | E8: 287733 | F8: 340452 | G8: =F8*(1+'Assumption Summary'!$C$21) -> 374497.2 | H8: =G8*(1+'Assumption Summary'!$C$21) -> 411946.92 | I8: =H8*(1+'Assumption Summary'!$C$21) -> 453141.61 | J8: =I8*(1+'Assumption Summary'!$C$21) -> 498455.77 | K8: =J8*(1+'Assumption Summary'!$C$21) -> 548301.35
A9: Sales, General and administrative | B9: 854120 | C9: 899023 | D9: 830022 | E9: 665950 | F9: 742821 | G9: =F9*(1+'Assumption Summary'!$C$22) -> 794818.47 | H9: =G9*(1+'Assumption Summary'!$C$22) -> 850455.76 | I9: =H9*(1+'Assumption Summary'!$C$22) -> 909987.67 | J9: =I9*(1+'Assumption Summary'!$C$22) -> 973686.8 | K9: =J9*(1+'Assumption Summary'!$C$22) -> 1041844.9
A10: Other operating expenses | B10: -19751 | C10: 300285 | D10: 28714 | E10: 137610 | F10: 6321 | G10: =G4*'Assumption Summary'!$C$23 -> 128974.11 | H10: =H4*'Assumption Summary'!$C$23 -> 143133.44 | I10: =I4*'Assumption Summary'!$C$23 -> 154618.79 | J10: =J4*'Assumption Summary'!$C$23 -> 170589.38 | K10: =K4*'Assumption Summary'!$C$23 -> 188469.1
A11: Total operating expenses | B11: =SUM(B8:B10) -> 1085224 | C11: =SUM(C8:C10) -> 1477460 | D11: =SUM(D8:D10) -> 1114875 | E11: =SUM(E8:E10) -> 1091293 | F11: =SUM(F8:F10) -> 1089594 | G11: =SUM(G8:G10) -> 1298289.8 | H11: =SUM(H8:H10) -> 1405536.1 | I11: =SUM(I8:I10) -> 1517748.1 | ... K11: =SUM(K8:K10) -> 1778615.3
A12: Operating income | B12: =B6-B11 -> 125985 | C12: =C6-C11 -> -293790 | D12: =D6-D11 -> -41801 | E12: =E6-E11 -> -81696 | F12: =F6-F11 -> -7027 | G12: =G6-G11 -> 205183.23 | H12: =H6-H11 -> 262994.56 | I12: =I6-I11 -> 284669.28 | ... K12: =K6-K11 -> 418400.83
A13: Interest Expense | B13: 36936 | C13: 44580 | D13: 62337 | E13: 72689 | F13: 84137 | G13: ='Assumption Summary'!$C$46*'Balance Sheet'!G32+'Assumption Summary'!C47*'Balance Sheet'!G27 -> 100534.22 | H13: ='Assumption Summary'!$C$46*'Balance Sheet'!H32+'Assumption Summary'!H3*'Balance Sheet'!H27 -> 97120.757 | I13: ='Assumption Summary'!$C$46*'Balance Sheet'!I32+'Assumption Summary'!I3*'Balance Sheet'!I27 -> 99063.173 | J13: ='Assumption Summary'!$C$46*'Balance Sheet'!J32+'Assumption Summary'!J3*'Balance Sheet'!J27 -> 101044.44 | K13: ='Assumption Summary'!$C$46*'Balance Sheet'!K32+'Assumption Summary'!K3*'Balance Sheet'!K27 -> 103065.32
A14: Other income (net) | B14: 22500 | C14: 24659 | D14: -1662 | E14: 49644 | F14: 21129 | G14: =G4*'Assumption Summary'!$C$24 -> 33090.28 | H14: =H4*'Assumption Summary'!$C$24 -> 36723.072 | I14: =I4*'Assumption Summary'!$C$24 -> 39669.814 | J14: =J4*'Assumption Summary'!$C$24 -> 43767.313 | K14: =K4*'Assumption Summary'!$C$24 -> 48354.629
A15: Income before taxes | B15: =B12-SUM(B13,-B14) -> 111549 | C15: =C12-SUM(C13,-C14) -> -313711 | D15: =D12-SUM(D13,-D14) -> -105800 | E15: =E12-SUM(E13,-E14) -> -104741 | F15: =F12-SUM(F13,-F14) -> -70035 | G15: =G12-SUM(G13,-G14) -> 137739.29 | H15: =H12-SUM(H13,-H14) -> 202596.87 | I15: =I12-SUM(I13,-I14) -> 225275.92 | ... K15: =K12-SUM(K13,-K14) -> 363690.13
A16: Provision for income taxes | B16: 21661 | C16: -25450 | D16: 14909 | E16: 29772 | F16: 44381 | G16: =G4*'Assumption Summary'!$C$25 -> 24268.577 | H16: =H4*'Assumption Summary'!$C$25 -> 26932.885 | I16: =I4*'Assumption Summary'!$C$25 -> 29094.04 | J16: =J4*'Assumption Summary'!$C$25 -> 32099.166 | K16: =K4*'Assumption Summary'!$C$25 -> 35463.527
A17: Net income from continuing operations | B17: =B15-B16 -> 89888 | C17: =C15-C16 -> -288261 | D17: =D15-D16 -> -120709 | E17: =E15-E16 -> -134513 | F17: =F15-F16 -> -114416 | G17: =G15-G16 -> 113470.71 | H17: =H15-H16 -> 175663.99 | I17: =I15-I16 -> 196181.88 | ... K17: =K15-K16 -> 328226.61
A18: Net income from discontinuing operations | B18: 0 | C18: 0 | D18: 0 | E18: 0 | F18: 0 | G18: 0 | H18: 0 | I18: 0 | J18: 0 | K18: 0
A19: Net income | B19: =SUM(B17:B18) -> 89888 | C19: =SUM(C17:C18) -> -288261 | D19: =SUM(D17:D18) -> -120709 | E19: =SUM(E17:E18) -> -134513 | F19: =SUM(F17:F18) -> -114416 | G19: =SUM(G17:G18) -> 113470.71 | H19: =SUM(H17:H18) -> 175663.99 | I19: =SUM(I17:I18) -> 196181.88 | ... K19: =SUM(K17:K18) -> 328226.61
A20: Preferred dividend
A21: Net income available to common shareholders | B21: =B19-B20 -> 89888 | C21: =C19-C20 -> -288261 | D21: =D19-D20 -> -120709 | E21: =E19-E20 -> -134513 | F21: =F19-F20 -> -114416 | G21: =G19-G20 -> 113470.71 | H21: =H19-H20 -> 175663.99 | I21: =I19-I20 -> 196181.88 | ... K21: =K19-K20 -> 328226.61
A22: Earnings per share
A23: Basic | B23: =B21/B26 -> 26.468787 | C23: =C21/C26 -> -84.882509 | D23: =D21/D26 -> -34.876914 | E23: =E21/E26 -> -36.984603 | F23: =F21/F26 -> -29.881431 | G23: =G21/G26 -> 29.634556 | H23: =H21/H26 -> 45.877249 | I23: =I21/I26 -> 51.2358 | ... K23: =K21/K26 -> 85.721234
A24: Diluted | B24: =B21/B27 -> 26.460995 | C24: =C21/C27 -> -84.882509 | D24: =D21/D27 -> -34.876914 | E24: =E21/E27 -> -36.984603 | F24: =F21/F27 -> -29.881431 | G24: =G21/G27 -> 29.634556 | H24: =H21/H27 -> 45.877249 | I24: =I21/I27 -> 51.2358 | ... K24: =K21/K27 -> 85.721234
A25: Weighted average shares outstanding in Millions
A26: Basic | B26: 3396 | C26: 3396 | D26: 3461 | E26: 3637 | F26: 3829 | G26: 3829 | H26: 3829 | I26: 3829 | J26: 3829 | K26: 3829
A27: Diluted | B27: 3397 | C27: 3396 | D27: 3461 | E27: 3637 | F27: 3829 | G27: 3829 | H27: 3829 | I27: 3829 | J27: 3829 | K27: 3829
A28: EBITDA | B28: 311210 | C28: 270060 | D28: 218700 | E28: 304749 | F28: 267315 | G28: =G21+G16+G13+('Balance Sheet'!G16-'Balance Sheet'!F16) -> 256496.55 | H28: =H21+H16+H13+('Balance Sheet'!H16-'Balance Sheet'!G16) -> 318305.13 | I28: =I21+I16+I13+('Balance Sheet'!I16-'Balance Sheet'!H16) -> 343298.34 | J28: =J21+J16+J13+('Balance Sheet'!J16-'Balance Sheet'!I16) -> 408963 | K28: =K21+K16+K13+('Balance Sheet'!K16-'Balance Sheet'!J16) -> 486480.66
A30: (1) Mistake adjustment: adjust formula from | B30: SUM('Revenue forecast'!M13:M16) | E30: to | F30: SUM('Revenue forecast'!M11:M16)
A32: Source: Refinitiv Eikon

Sheet Balance Sheet
A1: Balance Sheet
B2: Historical Values | G2: Forecasted Values
A3: Fiscal year ends in March. INR in millions except per share data. | B3: 2017 | C3: 2018 | D3: 2019 | E3: 2020 | F3: 2021 | G3: 2022F | H3: 2023F | I3: 2024F | J3: 2025F | K3: 2026F
A4: Assets | B4: =B22 -> 3313506 | C4: =C22 -> 3071946 | D4: =D22 -> 3221213 | E4: =E22 -> 3431258 | F4: =F22 -> 3306201 | G4: =G22 -> 3998073.7 | H4: =H22 -> 4447684.3 | I4: =I22 -> 4911609.1 | ... K4: =K22 -> 6196610.1
A5: Current assets
A6: Cash and cash equivalents | B6: 492395 | C6: 416638 | D6: 441589 | E6: 317000 | F6: 381590 | G6: =G44-(SUM(G7:G10,G16:G20)) -> 266608.82 | H6: =H44-(SUM(H7:H10,H16:H20)) -> 156913.56 | I6: =I44-(SUM(I7:I10,I16:I20)) -> 434569.4 | J6: =J44-(SUM(J7:J10,J16:J20)) -> 530343.51 | K6: =K44-(SUM(K7:K10,K16:K20)) -> 1022207.2
A7: Receivables | B7: 349771 | C7: 373466 | D7: 316765 | E7: 713237 | F7: 656055 | G7: =NWC!G2 -> 615356.21 | H7: =NWC!H2 -> 928817.87 | I7: =NWC!I2 -> 891020.96 | J7: =NWC!J2 -> 1083642.4 | K7: =NWC!K2 -> 979024.58
A8: Inventories | B8: 443981 | C8: 401916 | D8: 382387 | E8: 376313 | F8: 367871 | G8: =NWC!G6 -> 567132.3 | H8: =NWC!H6 -> 617468.51 | I8: =NWC!I6 -> 679065.8 | J8: =NWC!J6 -> 736581.23 | K8: =NWC!K6 -> 826402.69
A9: Prepaid expenses | B9: 14404 | C9: 12107 | D9: 13344 | E9: 12201 | F9: 20293 | G9: =NWC!G10 -> 20590.425 | H9: =NWC!H10 -> 22850.929 | I9: =NWC!I10 -> 24684.539 | J9: =NWC!J10 -> 27234.207 | K9: =NWC!K10 -> 30088.665
A10: Other current assets | B10: 59178 | C10: 30185 | D10: 41789 | E10: 50125 | F10: 43967 | G10: =NWC!G13 -> 64104.128 | H10: =NWC!H13 -> 71141.752 | I10: =NWC!I13 -> 76850.327 | J10: =NWC!J13 -> 84788.205 | K10: =NWC!K13 -> 93674.981
A11: Total current assets | B11: =SUM(B6:B10) -> 1359729 | C11: =SUM(C6:C10) -> 1234312 | D11: =SUM(D6:D10) -> 1195874 | E11: =SUM(E6:E10) -> 1468876 | F11: =SUM(F6:F10) -> 1469776 | G11: =SUM(G6:G10) -> 1533791.9 | H11: =SUM(H6:H10) -> 1797192.6 | I11: =SUM(I6:I10) -> 2106191 | ... K11: =SUM(K6:K10) -> 2951398.1
A12: Non-current assets
A13: Property, plant and equipment
A14: Gross property, plant and equipment | B14: 1446194 | C14: 1532092 | D14: 1792332 | E14: 1969974 | F14: 2029518 | G14: =F14*(1+'Assumption Summary'!$C$31) -> 2070108.4 | H14: =G14*(1+'Assumption Summary'!$C$31) -> 2111510.5 | I14: =H14*(1+'Assumption Summary'!$C$31) -> 2153740.7 | J14: =I14*(1+'Assumption Summary'!$C$31) -> 2196815.6 | K14: =J14*(1+'Assumption Summary'!$C$31) -> 2240751.9
A15: Accumulated Depreciation | B15: 546086 | C15: 720512 | D15: 864755 | E15: 1024896 | F15: 1118366 | G15: =F15/F14 *G14 -> 1140733.3 | H15: =G15/G14 *H14 -> 1163548 | I15: =H15/H14 *I14 -> 1186818.9 | J15: =I15/I14 *J14 -> 1210555.3 | K15: =J15/J14 *K14 -> 1234766.4
A16: Net property, plant and equipment | B16: =B14-B15 -> 900108 | C16: =C14-C15 -> 811580 | D16: =D14-D15 -> 927577 | E16: =E14-E15 -> 945078 | F16: =F14-F15 -> 911152 | G16: =G14-G15 -> 929375.04 | H16: =H14-H15 -> 947962.54 | I16: =I14-I15 -> 966921.79 | ... K16: =K14-K15 -> 1005985.4
A17: Goodwill | B17: 1165 | C17: 7479 | D17: 7771 | E17: 8037 | F17: 8072 | G17: =F17*(1+'Assumption Summary'!C29) -> 8072 | H17: =G17*(1+'Assumption Summary'!$C$29) -> 8072 | I17: =H17*(1+'Assumption Summary'!$C$29) -> 8072 | J17: =I17*(1+'Assumption Summary'!$C$29) -> 8072 | K17: =J17*(1+'Assumption Summary'!$C$29) -> 8072
A18: Intangible assets | B18: 713201 | C18: 612124 | D18: 691946 | E18: 643600 | F18: 571842 | G18: ='Assumption Summary'!$C$32*'Income Statement'!G4 -> 998954.15 | H18: ='Assumption Summary'!$C$32*'Income Statement'!H4 -> 1108623.6 | I18: ='Assumption Summary'!$C$32*'Income Statement'!I4 -> 1197582 | J18: ='Assumption Summary'!$C$32*'Income Statement'!J4 -> 1321280.4 | K18: ='Assumption Summary'!$C$32*'Income Statement'!K4 -> 1459765.7
A19: Long Term Investments | B19: 243316 | C19: 317395 | D19: 265440 | E19: 266846 | F19: 224566 | G19: ='Assumption Summary'!$C$30*'Income Statement'!G4 -> 374976.59 | H19: ='Assumption Summary'!$C$30*'Income Statement'!H4 -> 416143.12 | I19: ='Assumption Summary'!$C$30*'Income Statement'!I4 -> 449535.38 | J19: ='Assumption Summary'!$C$30*'Income Statement'!J4 -> 495967.93 | K19: ='Assumption Summary'!$C$30*'Income Statement'!K4 -> 547951.06
A20: Other long-term assets | B20: 95987 | C20: 89056 | D20: 132605 | E20: 98821 | F20: 120793 | G20: ='Assumption Summary'!$C$33*'Income Statement'!G4 -> 152904.02 | H20: ='Assumption Summary'!$C$33*'Income Statement'!H4 -> 169690.47 | I20: ='Assumption Summary'!$C$33*'Income Statement'!I4 -> 183306.82 | J20: ='Assumption Summary'!$C$33*'Income Statement'!J4 -> 202240.59 | K20: ='Assumption Summary'!$C$33*'Income Statement'!K4 -> 223437.73
A21: Total non-current assets | B21: =SUM(B16:B20) -> 1953777 | C21: =SUM(C16:C20) -> 1837634 | D21: =SUM(D16:D20) -> 2025339 | E21: =SUM(E16:E20) -> 1962382 | F21: =SUM(F16:F20) -> 1836425 | G21: =SUM(G16:G20) -> 2464281.8 | H21: =SUM(H16:H20) -> 2650491.7 | I21: =SUM(I16:I20) -> 2805418 | ... K21: =SUM(K16:K20) -> 3245212
A22: Total assets | B22: =SUM(B21,B11) -> 3313506 | C22: =SUM(C21,C11) -> 3071946 | D22: =SUM(D21,D11) -> 3221213 | E22: =SUM(E21,E11) -> 3431258 | F22: =SUM(F21,F11) -> 3306201 | G22: =SUM(G21,G11) -> 3998073.7 | H22: =SUM(H21,H11) -> 4447684.3 | I22: =SUM(I21,I11) -> 4911609.1 | ... K22: =SUM(K21,K11) -> 6196610.1
A24: Liabilities and stockholders' equity
A25: Liabilities
A26: Current liabilities
A27: Short-term debt | B27: 167949 | C27: 201503 | D27: 163625 | E27: 216628 | F27: 173784 | G27: =F27*(1+'Assumption Summary'!$C$36) -> 177259.68 | H27: =G27*(1+'Assumption Summary'!$C$36) -> 180804.87 | I27: =H27*(1+'Assumption Summary'!$C$36) -> 184420.97 | J27: =I27*(1+'Assumption Summary'!$C$36) -> 188109.39 | K27: =J27*(1+'Assumption Summary'!$C$36) -> 191871.58
A28: Accounts payable | B28: 781422 | C28: 738582 | D28: 676833 | E28: 776430 | F28: 714967 | G28: =NWC!G17 -> 1060881.7 | H28: =NWC!H17 -> 1154153 | I28: =NWC!I17 -> 1270181.4 | J28: =NWC!J17 -> 1376876.8 | K28: =NWC!K17 -> 1545680.4
A29: Other current liabilities | B29: 482824 | C29: 514489 | D29: 564082 | E29: 584434 | F29: 618079 | G29: =NWC!G24 -> 786604.36 | H29: =NWC!H24 -> 872961.14 | I29: =NWC!I24 -> 943009.51 | J29: =NWC!J24 -> 1040413.1 | K29: =NWC!K24 -> 1149460.3
A30: Total current liabilities | B30: =SUM(B27:B29) -> 1432195 | C30: =SUM(C27:C29) -> 1454574 | D30: =SUM(D27:D29) -> 1404540 | E30: =SUM(E27:E29) -> 1577492 | F30: =SUM(F27:F29) -> 1506830 | G30: =SUM(G27:G29) -> 2024745.7 | H30: =SUM(H27:H29) -> 2207919 | I30: =SUM(I27:I29) -> 2397611.8 | ... K30: =SUM(K27:K29) -> 2887012.2
A31: Non-current liabilities
A32: Long-term debt | B32: 611995 | C32: 709737 | D32: 884786 | E32: 985248 | F32: 1037216 | G32: =('Assumption Summary'!$C$37+1)*'Balance Sheet'!F32 -> 1057960.3 | H32: =('Assumption Summary'!$C$37+1)*'Balance Sheet'!G32 -> 1079119.5 | I32: =('Assumption Summary'!$C$37+1)*'Balance Sheet'!H32 -> 1100701.9 | J32: =('Assumption Summary'!$C$37+1)*'Balance Sheet'!I32 -> 1122716 | K32: =('Assumption Summary'!$C$37+1)*'Balance Sheet'!J32 -> 1145170.3
A33: Deferred taxes liabilities | B33: 61258 | C33: 14910 | D33: 19419 | E33: 15559 | F33: 15584 | G33: =NWC!G21 -> 36067.181 | H33: =NWC!H21 -> 40026.79 | I33: =NWC!I21 -> 43238.63 | J33: =NWC!J21 -> 47704.752 | K33: =NWC!K21 -> 52704.757
A34: Minority interest | B34: 5251 | C34: 5231 | D34: 8136 | E34: 15735 | F34: 42711 | G34: ='Assumption Summary'!$C$35*'Income Statement'!G4 -> 21932.307 | H34: ='Assumption Summary'!$C$35*'Income Statement'!H4 -> 24340.129 | I34: ='Assumption Summary'!$C$35*'Income Statement'!I4 -> 26293.236 | J34: ='Assumption Summary'!$C$35*'Income Statement'!J4 -> 29009.067 | K34: ='Assumption Summary'!$C$35*'Income Statement'!K4 -> 32049.55
A35: Other long-term liabilities | B35: 248528 | C35: 285698 | D35: 273547 | E35: 284757 | F35: 258248 | G35: ='Assumption Summary'!$C$38*'Income Statement'!G4 -> 384429.54 | H35: ='Assumption Summary'!$C$38*'Income Statement'!H4 -> 426633.85 | I35: ='Assumption Summary'!$C$38*'Income Statement'!I4 -> 460867.91 | J35: ='Assumption Summary'!$C$38*'Income Statement'!J4 -> 508471 | K35: ='Assumption Summary'!$C$38*'Income Statement'!K4 -> 561764.59
A36: Total non-current liabilities | B36: =SUM(B32:B35) -> 927032 | C36: =SUM(C32:C35) -> 1015576 | D36: =SUM(D32:D35) -> 1185888 | E36: =SUM(E32:E35) -> 1301299 | F36: =SUM(F32:F35) -> 1353759 | G36: =SUM(G32:G35) -> 1500389.3 | H36: =SUM(H32:H35) -> 1570120.3 | I36: =SUM(I32:I35) -> 1631101.7 | ... K36: =SUM(K32:K35) -> 1791689.2
A37: Total liabilities | B37: =SUM(B36,B30) -> 2359227 | C37: =SUM(C36,C30) -> 2470150 | D37: =SUM(D36,D30) -> 2590428 | E37: =SUM(E36,E30) -> 2878791 | F37: =SUM(F36,F30) -> 2860589 | G37: =SUM(G36,G30) -> 3525135.1 | H37: =SUM(H36,H30) -> 3778039.3 | I37: =SUM(I36,I30) -> 4028713.5 | ... K37: =SUM(K36,K30) -> 4678701.4
A38: Stockholders' equity
A39: Common stock | B39: 6792 | C39: 6792 | D39: 7195 | E39: 7658 | F39: 7659 | G39: =F39*(1+'Assumption Summary'!$C39) -> 7659 | H39: =G39*(1+'Assumption Summary'!$C39) -> 7659 | I39: =H39*(1+'Assumption Summary'!$C39) -> 7659 | J39: =I39*(1+'Assumption Summary'!$C39) -> 7659 | K39: =J39*(1+'Assumption Summary'!$C39) -> 7659
A40: Additional paid-in capital | B40: 188919 | C40: 188919 | D40: 218729 | E40: 252966 | F40: 141435 | G40: =F40*(1+'Assumption Summary'!$C40) -> 141435 | H40: =G40*(1+'Assumption Summary'!$C40) -> 141435 | I40: =H40*(1+'Assumption Summary'!$C40) -> 141435 | J40: =I40*(1+'Assumption Summary'!$C40) -> 141435 | K40: =J40*(1+'Assumption Summary'!$C40) -> 141435
A41: Retained earnings | B41: 676602 | C41: 388341 | D41: 267632 | E41: 133119 | F41: 18703 | G41: =F41+'Income Statement'!G21 -> 132173.71 | H41: =G41+'Income Statement'!H21 -> 307837.7 | I41: =H41+'Income Statement'!I21 -> 504019.58 | J41: =I41+'Income Statement'!J21 -> 760500.54 | K41: =J41+'Income Statement'!K21 -> 1088727.1
...

Sheet Cash Flow Statement
A1: Cash Flow Statement
B2: Historical Values | G2: Forecasted Values
A3: Fiscal year ends in March. INR in millions except per share data. | B3: 2017 | C3: 2018 | D3: 2019 | E3: 2020 | F3: 2021 | G3: 2022F | H3: 2023F | I3: 2024F | J3: 2025F | K3: 2026F
A4: Cash Flows From Operating Activities
A5: Net income | B5: 89888 | C5: -288261 | D5: -120709 | E5: -134513 | F5: -114416 | G5: ='Income Statement'!G21 -> 113470.71 | H5: ='Income Statement'!H21 -> 175663.99 | I5: ='Income Statement'!I21 -> 196181.88 | J5: ='Income Statement'!J21 -> 256480.96 | K5: ='Income Statement'!K21 -> 328226.61
A6: Depreciation & amortization | B6: 215536 | C6: 235906 | D6: 214254 | E6: 235467 | F6: 248357 | G6: ='Balance Sheet'!G15-'Balance Sheet'!F15 -> 22367.32 | H6: ='Balance Sheet'!H15-'Balance Sheet'!G15 -> 22814.666 | I6: ='Balance Sheet'!I15-'Balance Sheet'!H15 -> 23270.96 | J6: ='Balance Sheet'!J15-'Balance Sheet'!I15 -> 23736.379 | K6: ='Balance Sheet'!K15-'Balance Sheet'!J15 -> 24211.107
A7: Change in working capital | B7: =SUM(B8:B13) -> -70315 | C7: =SUM(C8:C13) -> 242682 | D7: =SUM(D8:D13) -> 171828 | E7: =SUM(E8:E13) -> 188489 | F7: =SUM(F8:F13) -> 7559 | G7: =SUM(G8:G13) -> 315305.85 | H7: =SUM(H8:H13) -> -200505.54 | I7: =SUM(I8:I13) -> 149025.61 | ... K7: =SUM(K8:K13) -> 272019.11
A8: Pre-paid expense | B8: 26673 | C8: 338960 | D8: 139023 | E8: 210460 | F8: 131392 | G8: =-('Balance Sheet'!G9-'Balance Sheet'!F9) -> -297.42453 | H8: =-('Balance Sheet'!H9-'Balance Sheet'!G9) -> -2260.5044 | I8: =-('Balance Sheet'!I9-'Balance Sheet'!H9) -> -1833.6101 | J8: =-('Balance Sheet'!J9-'Balance Sheet'!I9) -> -2549.6684 | K8: =-('Balance Sheet'!K9-'Balance Sheet'!J9) -> -2854.4573
A9: Accounts Receivable | B9: -140312 | C9: -88790 | D9: 100142 | E9: -68142 | F9: 4660 | G9: =-('Balance Sheet'!G7-'Balance Sheet'!F7) -> 40698.794 | H9: =-('Balance Sheet'!H7-'Balance Sheet'!G7) -> -313461.66 | I9: =-('Balance Sheet'!I7-'Balance Sheet'!H7) -> 37796.903 | J9: =-('Balance Sheet'!J7-'Balance Sheet'!I7) -> -192621.41 | K9: =-('Balance Sheet'!K7-'Balance Sheet'!J7) -> 104617.79
A10: Inventories | B10: -35604 | C10: 20686 | D10: 23255 | E10: 38145 | F10: 5974 | G10: =-('Balance Sheet'!G8-'Balance Sheet'!F8) -> -199261.3 | H10: =-('Balance Sheet'!H8-'Balance Sheet'!G8) -> -50336.212 | I10: =-('Balance Sheet'!I8-'Balance Sheet'!H8) -> -61597.287 | J10: =-('Balance Sheet'!J8-'Balance Sheet'!I8) -> -57515.437 | K10: =-('Balance Sheet'!K8-'Balance Sheet'!J8) -> -89821.461
A11: Other Assets | B11: 1513 | C11: 2949 | D11: -28309 | E11: 38535 | F11: -53122 | G11: =-('Balance Sheet'!G10-'Balance Sheet'!F10) -> -20137.128 | H11: =-('Balance Sheet'!H10-'Balance Sheet'!G10) -> -7037.624 | I11: =-('Balance Sheet'!I10-'Balance Sheet'!H10) -> -5708.5746 | J11: =-('Balance Sheet'!J10-'Balance Sheet'!I10) -> -7937.8776 | K11: =-('Balance Sheet'!K10-'Balance Sheet'!J10) -> -8886.7764
A12: Accounts Payable | B12: 73203 | C12: -46837 | D12: -80848 | E12: 57482 | F12: -70119 | G12: ='Balance Sheet'!G28-'Balance Sheet'!F28 -> 345914.67 | H12: ='Balance Sheet'!H28-'Balance Sheet'!G28 -> 93271.306 | I12: ='Balance Sheet'!I28-'Balance Sheet'!H28 -> 116028.38 | J12: ='Balance Sheet'!J28-'Balance Sheet'!I28 -> 106695.43 | K12: ='Balance Sheet'!K28-'Balance Sheet'!J28 -> 168803.56
A13: Other Operating Cash Flow | B13: 4212 | C13: 15714 | D13: 18565 | E13: -87991 | F13: -11226 | G13: =('Balance Sheet'!G29-'Balance Sheet'!F29)-('Balance Sheet'!G10-'Balance Sheet'!F10) -> 148388.24 | H13: =('Balance Sheet'!H29-'Balance Sheet'!G29)-('Balance Sheet'!H10-'Balance Sheet'!G10) -> 79319.151 | I13: =('Balance Sheet'!I29-'Balance Sheet'!H29)-('Balance Sheet'!I10-'Balance Sheet'!H10) -> 64339.795 | J13: =('Balance Sheet'!J29-'Balance Sheet'!I29)-('Balance Sheet'!J10-'Balance Sheet'!I10) -> 89465.665 | K13: =('Balance Sheet'!K29-'Balance Sheet'!J29)-('Balance Sheet'!K10-'Balance Sheet'!J10) -> 100160.44
A14: Net cash provided by (used for) operating activities | B14: 235109 | C14: 190328 | D14: 265373 | E14: 289443 | F14: 141500 | G14: =SUM(G5,G6,G7) -> 451143.89 | H14: =SUM(H5,H6,H7) -> -2026.8915 | I14: =SUM(I5,I6,I7) -> 368478.45 | J14: =SUM(J5,J6,J7) -> 215754.05 | K14: =SUM(K5,K6,K7) -> 624456.82
A15: Cash Flows From Investing Activities
A16: Investments in property, plant, and equipment | B16: -198654 | C16: -174196 | D16: -143192 | E16: -117757 | F16: -90394 | G16: =-('Balance Sheet'!G14-'Balance Sheet'!F14) -> -40590.36 | H16: =-('Balance Sheet'!H14-'Balance Sheet'!G14) -> -41402.167 | I16: =-('Balance Sheet'!I14-'Balance Sheet'!H14) -> -42230.211 | J16: =-('Balance Sheet'!J14-'Balance Sheet'!I14) -> -43074.815 | K16: =-('Balance Sheet'!K14-'Balance Sheet'!J14) -> -43936.311
A17: Purchases of investments | B17: 39836 | C17: 89103 | D17: -57587 | E17: -360 | F17: 122394 | G17: =-('Balance Sheet'!G19-'Balance Sheet'!F19)-('Balance Sheet'!G17-'Balance Sheet'!F17) -> -150410.59 | H17: =-('Balance Sheet'!H19-'Balance Sheet'!G19)-('Balance Sheet'!H17-'Balance Sheet'!G17) -> -41166.526 | I17: =-('Balance Sheet'!I19-'Balance Sheet'!H19)-('Balance Sheet'!I17-'Balance Sheet'!H17) -> -33392.262 | J17: =-('Balance Sheet'!J19-'Balance Sheet'!I19)-('Balance Sheet'!J17-'Balance Sheet'!I17) -> -46432.552 | K17: =-('Balance Sheet'!K19-'Balance Sheet'!J19)-('Balance Sheet'!K17-'Balance Sheet'!J17) -> -51983.128
A18: Purchases of intangibles | B18: -152135 | C18: -178840 | D18: -153829 | E18: -84298 | F18: -61290 | G18: =-('Balance Sheet'!G18-'Balance Sheet'!F18) -> -427112.15 | H18: =-('Balance Sheet'!H18-'Balance Sheet'!G18) -> -109669.44 | I18: =-('Balance Sheet'!I18-'Balance Sheet'!H18) -> -88958.456 | J18: =-('Balance Sheet'!J18-'Balance Sheet'!I18) -> -123698.36 | K18: =-('Balance Sheet'!K18-'Balance Sheet'!J18) -> -138485.34
A19: Other investing activities | B19: 48937 | C19: 66821 | D19: 12905 | E19: -58849 | F19: -18461 | G19: =-('Balance Sheet'!G20-'Balance Sheet'!F20) -> -32111.016 | H19: =-('Balance Sheet'!H20-'Balance Sheet'!G20) -> -16786.454 | I19: =-('Balance Sheet'!I20-'Balance Sheet'!H20) -> -13616.346 | J19: =-('Balance Sheet'!J20-'Balance Sheet'!I20) -> -18933.779 | K19: =-('Balance Sheet'!K20-'Balance Sheet'!J20) -> -21197.134
A20: Net cash provided by (used for) investing activities | B20: -262016 | C20: -197112 | D20: -341703 | E20: -261264 | F20: -47751 | G20: =SUM(G16:G19) -> -650224.12 | H20: =SUM(H16:H19) -> -209024.58 | I20: =SUM(I16:I19) -> -178197.27 | J20: =SUM(J16:J19) -> -232139.51 | K20: =SUM(K16:K19) -> -255601.91
A21: Cash Flows From Financing Activities
A22: Net debt | B22: 1900 | C22: 110164 | D22: 86854 | E22: 199990 | F22: 41781 | G22: =('Balance Sheet'!G27-'Balance Sheet'!F27)+('Balance Sheet'!G32-'Balance Sheet'!F32) -> 24220 | H22: =('Balance Sheet'!H27-'Balance Sheet'!G27)+('Balance Sheet'!H32-'Balance Sheet'!G32) -> 24704.4 | I22: =('Balance Sheet'!I27-'Balance Sheet'!H27)+('Balance Sheet'!I32-'Balance Sheet'!H32) -> 25198.488 | J22: =('Balance Sheet'!J27-'Balance Sheet'!I27)+('Balance Sheet'!J32-'Balance Sheet'!I32) -> 25702.458 | K22: =('Balance Sheet'!K27-'Balance Sheet'!J27)+('Balance Sheet'!K32-'Balance Sheet'!J32) -> 26216.507
A23: Common Stock Issued | B23: 0 | C23: 0 | D23: 38888 | E23: 26025 | F23: 37686 | G23: ='Balance Sheet'!G40-'Balance Sheet'!F40 -> 0 | H23: ='Balance Sheet'!H40-'Balance Sheet'!G40 -> 0 | I23: ='Balance Sheet'!I40-'Balance Sheet'!H40 -> 0 | J23: ='Balance Sheet'!J40-'Balance Sheet'!I40 -> 0 | K23: ='Balance Sheet'!K40-'Balance Sheet'!J40 -> 0
A24: Dividend paid | B24: 0 | C24: 0 | D24: 0 | E24: -16 | F24: -15 | G24: 0 | H24: 0 | I24: 0 | J24: 0 | K24: 0
A25: Other financing activities | B25: -55066 | C25: -70998 | D25: -75974 | E25: -81515 | F25: -93498 | G25: =SUM('Balance Sheet'!G33:G35)-SUM('Balance Sheet'!F33:F35)+'Balance Sheet'!G42-'Balance Sheet'!F42 -> 39741.924 | H25: =SUM('Balance Sheet'!H33:H35)-SUM('Balance Sheet'!G33:G35)+'Balance Sheet'!H42-'Balance Sheet'!G42 -> 69614.188 | I25: =SUM('Balance Sheet'!I33:I35)-SUM('Balance Sheet'!H33:H35)+'Balance Sheet'!I42-'Balance Sheet'!H42 -> 56467.607 | J25: =SUM('Balance Sheet'!J33:J35)-SUM('Balance Sheet'!I33:I35)+'Balance Sheet'!J42-'Balance Sheet'!I42 -> 78519.242 | K25: =SUM('Balance Sheet'!K33:K35)-SUM('Balance Sheet'!J33:J35)+'Balance Sheet'!K42-'Balance Sheet'!J42 -> 87905.481
A26: Net cash provided by (used for) financing activities | B26: -53166 | C26: 39166 | D26: 49768 | E26: 144484 | F26: -14046 | G26: =SUM(G22:G25) -> 63961.924 | H26: =SUM(H22:H25) -> 94318.588 | I26: =SUM(I22:I25) -> 81666.095 | J26: =SUM(J22:J25) -> 104221.7 | K26: =SUM(K22:K25) -> 114121.99
A27: Discrepancies adjustment | B27: 13064 | C27: -14109 | D27: 10557 | E27: 4538 | F27: 3315 | G27: =IF(F30+SUM(G26,G20,G14)>'Balance Sheet'!G6,(F30+SUM(G26,G20,G14))-'Balance Sheet'!G6,-(F30+SUM(G26,G20,G14))+'Balance Sheet'!G6) -> 20137.128 | H27: =IF(G30+SUM(H26,H20,H14)>'Balance Sheet'!H6,(G30+SUM(H26,H20,H14))-'Balance Sheet'!H6,-(G30+SUM(H26,H20,H14))+'Balance Sheet'!H6) -> 7037.624 | I27: =IF(H30+SUM(I26,I20,I14)>'Balance Sheet'!I6,(H30+SUM(I26,I20,I14))-'Balance Sheet'!I6,-(H30+SUM(I26,I20,I14))+'Balance Sheet'!I6) -> 5708.5746 | J27: =IF(I30+SUM(J26,J20,J14)>'Balance Sheet'!J6,(I30+SUM(J26,J20,J14))-'Balance Sheet'!J6,-(I30+SUM(J26,J20,J14))+'Balance Sheet'!J6) -> 7937.8776 | K27: =IF(J30+SUM(K26,K20,K14)>'Balance Sheet'!K6,(J30+SUM(K26,K20,K14))-'Balance Sheet'!K6,-(J30+SUM(K26,K20,K14))+'Balance Sheet'!K6) -> 8886.7764
A28: Net change in cash | B28: -16412 | C28: -75757 | D28: 24951 | E28: -124589 | F28: 64590 | G28: =SUM(G26,G20,G14,G27) -> -114981.18 | H28: =SUM(H26,H20,H14,H27) -> -109695.26 | I28: =SUM(I26,I20,I14,I27) -> 277655.84 | J28: =SUM(J26,J20,J14,J27) -> 95774.114 | K28: =SUM(K26,K20,K14,K27) -> 491863.67
A29: Cash at beginning of period | B29: 508807 | C29: 492395 | D29: 416638 | E29: 441589 | F29: 317000 | G29: ='Balance Sheet'!F6 -> 381590 | H29: =G30 -> 266608.82 | I29: =H30 -> 156913.56 | J29: =I30 -> 434569.4 | K29: =J30 -> 530343.51
A30: Cash at end of period | B30: 492395 | C30: 416638 | D30: 441589 | E30: 317000 | F30: 381590 | G30: =G29+G28 -> 266608.82 | H30: =H29+H28 -> 156913.56 | I30: =I29+I28 -> 434569.4 | J30: =J29+J28 -> 530343.51 | K30: =K29+K28 -> 1022207.2
A31: Free Cash Flow
A32: Operating cash flow | B32: 235109 | C32: 190328 | D32: 265373 | E32: 289443 | F32: 141500 | G32: =G14 -> 451143.89 | H32: =H14 -> -2026.8915 | I32: =I14 -> 368478.45 | J32: =J14 -> 215754.05 | K32: =K14 -> 624456.82
A33: Capital expenditure | B33: -350789 | C33: -353036 | D33: -297021 | E33: -202055 | F33: -151684 | G33: =G16+G6 -> -18223.04 | H33: =H16+H6 -> -18587.501 | I33: =I16+I6 -> -18959.251 | J33: =J16+J6 -> -19338.436 | K33: =K16+K6 -> -19725.205
A34: Free cash flow | B34: -115680 | C34: -162708 | D34: -31648 | E34: 87388 | F34: -10184 | G34: =SUM(G32:G33) -> 432920.85 | H34: =SUM(H32:H33) -> -20614.392 | I34: =SUM(I32:I33) -> 349519.2 | J34: =SUM(J32:J33) -> 196415.61 | K34: =SUM(K32:K33) -> 604731.62
A36: Balance check | B36: =B30-'Balance Sheet'!B6 -> 0 | C36: =C30-'Balance Sheet'!C6 -> 0 | D36: =D30-'Balance Sheet'!D6 -> 0 | E36: =E30-'Balance Sheet'!E6 -> 0 | F36: =F30-'Balance Sheet'!F6 -> 0 | G36: =G30-'Balance Sheet'!G6 -> 0 | H36: =H30-'Balance Sheet'!H6 -> 0 | I36: =I30-'Balance Sheet'!I6 -> 0 | ... K36: =K30-'Balance Sheet'!K6 -> 0
A37: Source: Refinitiv Eikon

Sheet FCFF and FCFE Valuation
A1: Free Cash Flow to Firm (FCFF) and Free Cash Flow to Equity (FCFE)
C5: ='Income Statement'!G3 -> 2022F | D5: ='Income Statement'!H3 -> 2023F | E5: ='Income Statement'!I3 -> 2024F | F5: ='Income Statement'!J3 -> 2025F | G5: ='Income Statement'!K3 -> 2026F | J5: Cost of Equity Calcuation using CAPM
B6: Net Income | C6: ='Income Statement'!G19 -> 113470.71 | D6: ='Income Statement'!H19 -> 175663.99 | E6: ='Income Statement'!I19 -> 196181.88 | F6: ='Income Statement'!J19 -> 256480.96 | G6: ='Income Statement'!K19 -> 328226.61 | J6: Risk Free Rate (5 year G-Sec) | O6: ='Assumption Summary'!C52 -> 0.072
B7: Depreciation and Amortization Charges | C7: ='Cash Flow Statement'!G6 -> 22367.32 | D7: ='Cash Flow Statement'!H6 -> 22814.666 | E7: ='Cash Flow Statement'!I6 -> 23270.96 | F7: ='Cash Flow Statement'!J6 -> 23736.379 | G7: ='Cash Flow Statement'!K6 -> 24211.107 | J7: Stock Beta (Ref: Refinitiv Eikon) | O7: ='Assumption Summary'!C53 -> 1.71
B8: Interest Expense | C8: ='Income Statement'!G13 -> 100534.22 | D8: ='Income Statement'!H13 -> 97120.757 | E8: ='Income Statement'!I13 -> 99063.173 | F8: ='Income Statement'!J13 -> 101044.44 | G8: ='Income Statement'!K13 -> 103065.32 | J8: Market Return Rm (Nifty 50 10 Year CAGR) | O8: ='Assumption Summary'!C54 -> 0.13
B9: Tax Rate | C9: ='Assumption Summary'!$C$42 -> 0.3 | D9: ='Assumption Summary'!$C$42 -> 0.3 | E9: ='Assumption Summary'!$C$42 -> 0.3 | F9: ='Assumption Summary'!$C$42 -> 0.3 | G9: ='Assumption Summary'!$C$42 -> 0.3 | J9: Cost of Equity | O9: =O6+O7*(O8-O6) -> 0.17118
B10: Fixed Capital Investment | C10: ='Cash Flow Statement'!G33*-1 -> 18223.04 | D10: ='Cash Flow Statement'!H33*-1 -> 18587.501 | E10: ='Cash Flow Statement'!I33*-1 -> 18959.251 | F10: ='Cash Flow Statement'!J33*-1 -> 19338.436 | G10: ='Cash Flow Statement'!K33*-1 -> 19725.205
B11: Working Capital Investment | C11: ='Cash Flow Statement'!G7*-1 -> -315305.85 | D11: ='Cash Flow Statement'!H7*-1 -> 200505.54 | E11: ='Cash Flow Statement'!I7*-1 -> -149025.61 | F11: ='Cash Flow Statement'!J7*-1 -> 64463.292 | G11: ='Cash Flow Statement'!K7*-1 -> -272019.11
B12: Free Cash Flow to Firm | C12: =C6+C7+(C8*(1-C9))-C10-C11 -> 503294.8 | D12: =D6+D7+(D8*(1-D9))-D10-D11 -> 47370.138 | E12: =E6+E7+(E8*(1-E9))-E10-E11 -> 418863.42 | F12: =F6+F7+(F8*(1-F9))-F10-F11 -> 267146.71 | G12: =G6+G7+(G8*(1-G9))-G10-G11 -> 676877.34
B13: Interest Expense | C13: =C8 -> 100534.22 | D13: =D8 -> 97120.757 | E13: =E8 -> 99063.173 | F13: =F8 -> 101044.44 | G13: =G8 -> 103065.32 | J13: Cost of Debt
B14: Tax Rate | C14: =C9 -> 0.3 | D14: =D9 -> 0.3 | E14: =E9 -> 0.3 | F14: =F9 -> 0.3 | G14: =G9 -> 0.3 | J14: Cost of Debt (Interest Expense/Total Debt) | O14: ='Income Statement'!K13/('Balance Sheet'!K27+'Balance Sheet'!K32) -> 0.077084591
B15: Increase in Debt | C15: ='Cash Flow Statement'!G22 -> 24220 | D15: ='Cash Flow Statement'!H22 -> 24704.4 | E15: ='Cash Flow Statement'!I22 -> 25198.488 | F15: ='Cash Flow Statement'!J22 -> 25702.458 | G15: ='Cash Flow Statement'!K22 -> 26216.507
B16: Free Cash Flow to Equity | C16: =C12-(C13*(1-C14))+C15 -> 457140.85 | D16: =D12-(D13*(1-D14))+D15 -> 4090.0077 | E16: =E12-(E13*(1-E14))+E15 -> 374717.68 | F16: =F12-(F13*(1-F14))+F15 -> 222118.07 | G16: =G12-(G13*(1-G14))+G15 -> 630948.12 | J16: Cost of Capital
J17: Cost of Equity | O17: =O9 -> 0.17118
J18: Weight of Equity in Target Capital Structure | O18: 0.6
B19: Terminal Value | J19: Cost of Debt | O19: =O14 -> 0.077084591
B20: Free Cash Flow to Firm | C20: =G12 -> 676877.34 | J20: Weight of Debt in Capital Structure | O20: =1-O18 -> 0.4
B21: Growth Rate | C21: ='Assumption Summary'!C51 -> 0.01 | J21: WACC | O21: =O17*O18+O19*O20 -> 0.13354184
B22: Cost of Capital | C22: =O21 -> 0.13354184
B23: Terminal Value | C23: =C20*(1+C21)/(C22-C21) -> 5533721.5
B25: FCFF Calculation | C25: FV | D25: Discounted | J25: Intrinsic Value of Share (FCFF Method)
B26: =C5 -> 2022F | C26: =C12 -> 503294.8 | D26: =C26/(1+O21) -> 444001.96 | J26: PV in INR Million | M26: =C32 -> 4248786.6
B27: =D5 -> 2023F | C27: =D12 -> 47370.138 | D27: =C27/(1+O21)^2 -> 36866.299 | J27: No of Shares Outstanding (In Million) | M27: ='Income Statement'!K26 -> 3829
B28: =E5 -> 2024F | C28: =E12 -> 418863.42 | D28: =C28/(1+O21)^3 -> 287580.72 | J28: Intrinsic Value | M28: =M26/M27 -> 1109.6335
B29: =F5 -> 2025F | C29: =F12 -> 267146.71 | D29: =C29/(1+O21)^4 -> 161807.86 | J29: Current Market Price of Share | M29: 400
B30: =G5 -> 2026F | C30: =G12 -> 676877.34 | D30: =C30/(1+O21)^5 -> 361678.1 | J30: Current Discount/Premium | M30: =(M29-M28)/M28 -> -0.63952061
B31: Terminal Value | C31: =C23 -> 5533721.5 | D31: =C31/(1+O21)^5 -> 2956851.6
B32: Present Value (PV) | C32: =D26+D27+D28+D29+D30+D31 -> 4248786.6
B35: FCFE Calculation | C35: FV | D35: Discounted | J35: Intrinsic Value of Share (FCFE Method)
B36: =B26 -> 2022F | C36: =C16 -> 457140.85 | D36: =C36/(1+$O$9) -> 390325.01 | J36: PV in INR Million | M36: =C42 -> 3542257.7
B37: =B27 -> 2023F | C37: =D16 -> 4090.0077 | D37: =C37/(1+$O$9)^2 -> 2981.7884 | J37: No of Shares Outstanding (In Million) | M37: =M27 -> 3829
B38: =B28 -> 2024F | C38: =E16 -> 374717.68 | D38: =C38/(1+$O$9)^3 -> 233256.23 | J38: Intrinsic Value | M38: =M36/M37 -> 925.113
B39: =B29 -> 2025F | C39: =F16 -> 222118.07 | D39: =C39/(1+$O$9)^4 -> 118056.33 | J39: Current Market Price of Share | M39: 400
B40: =B30 -> 2026F | C40: =G16 -> 630948.12 | D40: =C40/(1+$O$9)^5 -> 286335.65 | J40: Current Discount/Premium | M40: =(M39-M38)/M38 -> -0.56762039
B41: =B31 -> Terminal Value | C41: =C23 -> 5533721.5 | D41: =C41/(1+$O$9)^5 -> 2511302.7
B42: Present Value (PV) | C42: =D36+D37+D38+D39+D40+D41 -> 3542257.7
B45: Intrinsic Value of Shares in INR | F45: =M38 -> 925.113 | H45: 11.65 EUR
B48: Value of Shares at December 16th 2022 (in INR) | F48: 419 | H48: 5.28 EUR
B51: Upside | F51: =(F45-F48)/F48 -> 1.2079069

Sheet Financial Ratios
A1: FINANCIAL RATIOS | B1: 2018 | C1: 2019 | D1: 2020 | E1: 2021 | F1: 2022F | G1: 2023F | H1: 2024F | I1: 2025F | J1: 2026F
A2: Profitability ratio
A3: Gross margin | B3: ='Income Statement'!C6/'Income Statement'!C5 -> 0.64480088 | C3: ='Income Statement'!D6/'Income Statement'!D5 -> 0.69788619 | D3: ='Income Statement'!E6/'Income Statement'!E5 -> 0.6783326 | E3: ='Income Statement'!F6/'Income Statement'!F5 -> 0.6360674 | F3: ='Income Statement'!G6/'Income Statement'!G5 -> 0.61543247 | G3: ='Income Statement'!H6/'Income Statement'!H5 -> 0.61543247 | H3: ='Income Statement'!I6/'Income Statement'!I5 -> 0.61543247 | I3: ='Income Statement'!J6/'Income Statement'!J5 -> 0.61543247 | J3: ='Income Statement'!K6/'Income Statement'!K5 -> 0.61543247
A4: Net Profit margin | B4: ='Income Statement'!C19/'Income Statement'!C4 -> -0.095470136 | C4: ='Income Statement'!D19/'Income Statement'!D4 -> -0.046236613 | D4: ='Income Statement'!E19/'Income Statement'!E4 -> -0.0538494 | E4: ='Income Statement'!F19/'Income Statement'!F4 -> -0.04108979 | F4: ='Income Statement'!G19/'Income Statement'!G4 -> 0.028752774 | G4: ='Income Statement'!H19/'Income Statement'!H4 -> 0.040108843 | H4: ='Income Statement'!I19/'Income Statement'!I4 -> 0.041466285 | I4: ='Income Statement'!J19/'Income Statement'!J4 -> 0.049136209 | J4: ='Income Statement'!K19/'Income Statement'!K4 -> 0.056915706
A5: ROE DuPont | B5: =B6*B7*B8*B9*B10 -> -0.60939472 | C5: =C6*C7*C8*C9*C10 -> -0.33255444 | D5: =D6*D7*D8*D9*D10 -> -0.38158829 | E5: =E6*E7*E8*E9*E10 -> -0.37510515 | F5: =F6*F7*F8*F9*F10 -> 0.39911633 | G5: =G6*G7*G8*G9*G10 -> 0.49672215 | H5: =H6*H7*H8*H9*H10 -> 0.40825802 | I5: =I6*I7*I8*I9*I10 -> 0.40501115 | J5: =J6*J7*J8*J9*J10 -> 0.39554203
A6: EBIT/ Sales | B6: =('Income Statement'!C19+'Income Statement'!C13+'Income Statement'!C16)/'Income Statement'!C5 -> -0.14660835 | C6: =('Income Statement'!D19+'Income Statement'!D13+'Income Statement'!D16)/'Income Statement'!D5 -> -0.028266669 | D6: =('Income Statement'!E19+'Income Statement'!E13+'Income Statement'!E16)/'Income Statement'!E5 -> -0.021535243 | E6: =('Income Statement'!F19+'Income Statement'!F13+'Income Statement'!F16)/'Income Statement'!F5 -> 0.0082856973 | F6: =('Income Statement'!G19+'Income Statement'!G13+'Income Statement'!G16)/'Income Statement'!G5 -> 0.09753501 | G6: =('Income Statement'!H19+'Income Statement'!H13+'Income Statement'!H16)/'Income Statement'!H5 -> 0.11054994 | H6: =('Income Statement'!I19+'Income Statement'!I13+'Income Statement'!I16)/'Income Statement'!I5 -> 0.11074505 | I6: =('Income Statement'!J19+'Income Statement'!J13+'Income Statement'!J16)/'Income Statement'!J5 -> 0.12058177 | J6: =('Income Statement'!K19+'Income Statement'!K13+'Income Statement'!K16)/'Income Statement'!K5 -> 0.13074845
A7: NI/EBT | B7: ='Income Statement'!C19/('Income Statement'!C19+'Income Statement'!C16) -> 0.91887438 | C7: ='Income Statement'!D19/('Income Statement'!D19+'Income Statement'!D16) -> 1.1409168 | D7: ='Income Statement'!E19/('Income Statement'!E19+'Income Statement'!E16) -> 1.284244 | E7: ='Income Statement'!F19/('Income Statement'!F19+'Income Statement'!F16) -> 1.6336974 | F7: ='Income Statement'!G19/('Income Statement'!G19+'Income Statement'!G16) -> 0.82380789 | G7: ='Income Statement'!H19/('Income Statement'!H19+'Income Statement'!H16) -> 0.8670617 | H7: ='Income Statement'!I19/('Income Statement'!I19+'Income Statement'!I16) -> 0.87085153 | I7: ='Income Statement'!J19/('Income Statement'!J19+'Income Statement'!J16) -> 0.88876862 | J7: ='Income Statement'!K19/('Income Statement'!K19+'Income Statement'!K16) -> 0.90248972
A8: EBT / EBIT | B8: =('Income Statement'!C19+'Income Statement'!C16)/('Income Statement'!C19+'Income Statement'!C13+'Income Statement'!C16) -> 1.1656442 | C8: =('Income Statement'!D19+'Income Statement'!D16)/('Income Statement'!D19+'Income Statement'!D13+'Income Statement'!D16) -> 2.4342544 | D8: =('Income Statement'!E19+'Income Statement'!E16)/('Income Statement'!E19+'Income Statement'!E13+'Income Statement'!E16) -> 3.267846 | E8: =('Income Statement'!F19+'Income Statement'!F16)/('Income Statement'!F19+'Income Statement'!F13+'Income Statement'!F16) -> -4.9663168 | F8: =('Income Statement'!G19+'Income Statement'!G16)/('Income Statement'!G19+'Income Statement'!G13+'Income Statement'!G16) -> 0.5780722 | G8: =('Income Statement'!H19+'Income Statement'!H16)/('Income Statement'!H19+'Income Statement'!H13+'Income Statement'!H16) -> 0.67595914 | H8: =('Income Statement'!I19+'Income Statement'!I16)/('Income Statement'!I19+'Income Statement'!I13+'Income Statement'!I16) -> 0.69456912 | I8: =('Income Statement'!J19+'Income Statement'!J16)/('Income Statement'!J19+'Income Statement'!J13+'Income Statement'!J16) -> 0.74066205 | J8: =('Income Statement'!K19+'Income Statement'!K16)/('Income Statement'!K19+'Income Statement'!K13+'Income Statement'!K16) -> 0.77918775
A9: Assets turnover | B9: ='Income Statement'!C4/(AVERAGE('Balance Sheet'!B22:C22)) -> 0.94570721 | C9: ='Income Statement'!D4/(AVERAGE('Balance Sheet'!C22:D22)) -> 0.82968824 | D9: ='Income Statement'!E4/(AVERAGE('Balance Sheet'!D22:E22)) -> 0.75098351 | E9: ='Income Statement'!F4/(AVERAGE('Balance Sheet'!E22:F22)) -> 0.82658343 | F9: ='Income Statement'!G4/(AVERAGE('Balance Sheet'!F22:G22)) -> 1.08058 | G9: ='Income Statement'!H4/(AVERAGE('Balance Sheet'!G22:H22)) -> 1.0371318 | H9: ='Income Statement'!I4/(AVERAGE('Balance Sheet'!H22:I22)) -> 1.0109989 | I9: ='Income Statement'!J4/(AVERAGE('Balance Sheet'!I22:J22)) -> 1.0049645 | J9: ='Income Statement'!K4/(AVERAGE('Balance Sheet'!J22:K22)) -> 0.98807155
A10: A/E | B10: =AVERAGE('Balance Sheet'!B22:C22)/AVERAGE('Balance Sheet'!B43:C43) -> 4.1035631 | C10: =AVERAGE('Balance Sheet'!C22:D22)/AVERAGE('Balance Sheet'!C43:D43) -> 5.1056758 | D10: =AVERAGE('Balance Sheet'!D22:E22)/AVERAGE('Balance Sheet'!D43:E43) -> 5.6221929 | E10: =AVERAGE('Balance Sheet'!E22:F22)/AVERAGE('Balance Sheet'!E43:F43) -> 6.7504266 | F10: =AVERAGE('Balance Sheet'!F22:G22)/AVERAGE('Balance Sheet'!F43:G43) -> 7.9519567 | G10: =AVERAGE('Balance Sheet'!G22:H22)/AVERAGE('Balance Sheet'!G43:H43) -> 7.3918071 | H10: =AVERAGE('Balance Sheet'!H22:I22)/AVERAGE('Balance Sheet'!H43:I43) -> 6.0283728 | I10: =AVERAGE('Balance Sheet'!I22:J22)/AVERAGE('Balance Sheet'!I43:J43) -> 5.0772181 | J10: =AVERAGE('Balance Sheet'!J22:K22)/AVERAGE('Balance Sheet'!J43:K43) -> 4.3539487
A11: Efficiency ratio
A12: Days of sales outstanding (DSO) | B12: =NWC!C4 -> 43.115636 | C12: =NWC!D4 -> 47.589739 | D12: =NWC!E4 -> 74.221065 | E12: =NWC!F4 -> 88.514769 | F12: =NWC!G4 -> 57.990186 | G12: =NWC!H4 -> 63.463813 | H12: =NWC!I4 -> 69.237547 | I12: =NWC!J4 -> 68.094508 | J12: =NWC!K4 -> 64.381332
A13: Days of inventory on hand (DOH) | B13: =NWC!C8 -> 4.3402778 | C13: =NWC!D8 -> 3.9209489 | D13: =NWC!E8 -> 3.9234243 | E13: =NWC!F8 -> 4.5740543 | F13: =NWC!G8 -> 5.225551 | G13: =NWC!H8 -> 4.5773252 | H13: =NWC!I8 -> 4.5177369 | I13: =NWC!J8 -> 4.5649885 | J13: =NWC!K8 -> 4.5680235
A14: Days payable outstanding (DPO) | B14: =NWC!C19 -> 149.04322 | C14: =NWC!D19 -> 165.6957 | D14: =NWC!E19 -> 175.75648 | E14: =NWC!F19 -> 157.72994 | F14: =NWC!G19 -> 130.84684 | G14: =NWC!H19 -> 147.06158 | H14: =NWC!I19 -> 149.0013 | I14: =NWC!J19 -> 147.45901 | J14: =NWC!K19 -> 147.36104
A15: Cash conversion cycle | B15: =B13+B12-B14 -> -101.5873 | C15: =C13+C12-C14 -> -114.18501 | D15: =D13+D12-D14 -> -97.611996 | E15: =E13+E12-E14 -> -64.641112 | F15: =F13+F12-F14 -> -67.6311 | G15: =G13+G12-G14 -> -79.020445 | H15: =H13+H12-H14 -> -75.246018 | I15: =I13+I12-I14 -> -74.799514 | J15: =J13+J12-J14 -> -78.411682
A16: Liquidity ratio
A17: Current ratio | B17: =AVERAGE('Balance Sheet'!B11:C11)/AVERAGE('Balance Sheet'!B30:C30) -> 0.89859667 | C17: =AVERAGE('Balance Sheet'!C11:D11)/AVERAGE('Balance Sheet'!C30:D30) -> 0.8499787 | D17: =AVERAGE('Balance Sheet'!D11:E11)/AVERAGE('Balance Sheet'!D30:E30) -> 0.89360208 | E17: =AVERAGE('Balance Sheet'!E11:F11)/AVERAGE('Balance Sheet'!E30:F30) -> 0.95277082 | F17: =AVERAGE('Balance Sheet'!F11:G11)/AVERAGE('Balance Sheet'!F30:G30) -> 0.85048945 | G17: =AVERAGE('Balance Sheet'!G11:H11)/AVERAGE('Balance Sheet'!G30:H30) -> 0.78697103 | H17: =AVERAGE('Balance Sheet'!H11:I11)/AVERAGE('Balance Sheet'!H30:I30) -> 0.84754261 | I17: =AVERAGE('Balance Sheet'!I11:J11)/AVERAGE('Balance Sheet'!I30:J30) -> 0.91320616 | J17: =AVERAGE('Balance Sheet'!J11:K11)/AVERAGE('Balance Sheet'!J30:K30) -> 0.98572142
A18: Quick ratio | B18: =((AVERAGE('Balance Sheet'!B6:C6)+AVERAGE('Balance Sheet'!B7:C7))/AVERAGE('Balance Sheet'!B30:C30)) -> 0.56543146 | C18: =((AVERAGE('Balance Sheet'!C6:D6)+AVERAGE('Balance Sheet'!C7:D7))/AVERAGE('Balance Sheet'!C30:D30)) -> 0.54158666 | D18: =((AVERAGE('Balance Sheet'!D6:E6)+AVERAGE('Balance Sheet'!D7:E7))/AVERAGE('Balance Sheet'!D30:E30)) -> 0.59978934 | E18: =((AVERAGE('Balance Sheet'!E6:F6)+AVERAGE('Balance Sheet'!E7:F7))/AVERAGE('Balance Sheet'!E30:F30)) -> 0.67044945 | F18: =((AVERAGE('Balance Sheet'!F6:G6)+AVERAGE('Balance Sheet'!F7:G7))/AVERAGE('Balance Sheet'!F30:G30)) -> 0.54355624 | G18: =((AVERAGE('Balance Sheet'!G6:H6)+AVERAGE('Balance Sheet'!G7:H7))/AVERAGE('Balance Sheet'!G30:H30)) -> 0.46488361 | H18: =((AVERAGE('Balance Sheet'!H6:I6)+AVERAGE('Balance Sheet'!H7:I7))/AVERAGE('Balance Sheet'!H30:I30)) -> 0.52357087 | I18: =((AVERAGE('Balance Sheet'!I6:J6)+AVERAGE('Balance Sheet'!I7:J7))/AVERAGE('Balance Sheet'!I30:J30)) -> 0.58756141 | J18: =((AVERAGE('Balance Sheet'!J6:K6)+AVERAGE('Balance Sheet'!J7:K7))/AVERAGE('Balance Sheet'!J30:K30)) -> 0.65822047
